Workbook

Sheet inputtables
A3: Table 7: Values of M at Cone Surface
A4: Mach/coneangle | B4: 0 | C4: 2.5 | D4: 5 | E4: 7.5 | F4: 10 | G4: 12.5 | H4: 15 | I4: 17.5 | J4: 20 | K4: 22.5 | L4: 25 | M4: 27.5 | N4: 30
A5: 1.1 | B5: 1.1 | C5: 1.0854 | D5: 1.0656 | E5: 1.0309 | F5: 0.9811 | G5: 0.9164
A6: 1.25 | B6: 1.25 | C6: 1.2248 | D6: 1.1997 | E6: 1.161 | F6: 1.1136 | G6: 1.0769 | H6: 1.0287 | I6: 0.9771 | J6: 0.9266 | K6: 0.8639 | L6: 0.7974
A7: 1.5 | B7: 1.5 | C7: 1.4866884 | D7: 1.4579318 | E7: 1.4197316 | F7: 1.3748579 | G7: 1.3248992 | H7: 1.2707392 | I7: 1.2127162 | J7: 1.1506488 | K7: 1.0837313 | L7: 1.0100703
A8: 1.75 | B8: 1.75 | C8: 1.7340335 | D8: 1.7004643 | E8: 1.6568045 | F8: 1.6064462 | G8: 1.5513276 | H8: 1.4925484 | I8: 1.4306418 | J8: 1.3657361 | K8: 1.2976505 | L8: 1.2259024 | M8: 1.1495789 | N8: 1.0669388
A9: 2 | B9: 2 | C9: 1.9808615 | D9: 1.9415254 | E9: 1.8912335 | F9: 1.8340453 | G9: 1.7721933 | H9: 1.7068837 | I9: 1.6386764 | J9: 1.5688572 | K9: 1.4940884 | L9: 1.417468 | M9: 1.3375202 | N9: 1.2535953
A10: 2.5 | B10: 2.5 | C10: 2.4729472 | D10: 2.4193976 | E10: 2.3528628 | F10: 2.2788768 | G10: 2.2001554 | H10: 2.1179422 | I10: 2.0327606 | J10: 1.9448503 | K10: 1.8543543 | L10: 1.7613748 | M10: 1.6659616 | N10: 1.5680718
A11: 3 | B11: 3 | C11: 2.96276 | D11: 2.8913832 | E11: 2.8048038 | F11: 2.701014 | G11: 2.6103929 | H11: 2.5067511 | I11: 2.3997895 | J11: 2.2899646 | K11: 2.1777409 | L11: 2.063583 | M11: 1.9479054 | N11: 1.8310067
A12: 3.5 | B12: 3.5 | C12: 3.4500939 | D12: 3.3571597 | E12: 3.2467499 | F12: 3.1275136 | G12: 3.0025569 | H12: 2.8731152 | I12: 2.7400668 | J12: 2.6043443 | K12: 2.466913 | L12: 2.3286833 | M12: 2.1904152 | N12: 2.0526629
A13: 4 | B13: 4 | C13: 3.93477 | D13: 3.8164543 | E13: 3.6783916 | F13: 3.530568 | G13: 3.3761469 | H13: 3.2166972 | I13: 3.0537628 | J13: 2.8889908 | K13: 2.7239783 | L13: 2.5600783 | M13: 2.3983186 | N13: 2.2393739
A14: 4.5 | B14: 4.5 | C14: 4.4166246 | D14: 4.269058 | E14: 4.0994611 | F14: 3.9189007 | G14: 3.730775 | H14: 3.5374323 | I14: 3.3414321 | J14: 3.1453333 | K14: 2.9513677 | L14: 2.7612386 | M14: 2.5760876 | N14: 2.3965344
A15: 5 | B15: 5 | C15: 4.8955305 | D15: 4.7148078 | E15: 4.5097079 | F15: 4.2921847 | G15: 4.0662668 | H15: 3.8355932 | I15: 3.6040616 | J15: 3.3752078 | K15: 3.1517935 | L15: 2.935687 | M15: 2.7279347 | N15: 2.5209133
A16: 6 | B16: 6 | C16: 5.8440686 | D16: 5.5852474 | E16: 5.2968787 | F16: 4.9927832 | G16: 4.6801702 | H16: 4.3668118 | I16: 4.0597311 | J16: 3.7640785 | K16: 3.4829712 | L16: 3.2178167 | M16: 2.9687934 | N16: 2.735258
A17: 7 | B17: 7 | C17: 6.7796857 | D17: 6.4269172 | E17: 6.0384888 | F17: 5.631801 | G17: 5.220485 | H17: 4.8178049 | I17: 4.4335119 | J17: 4.0731395 | K17: 3.7388047 | L17: 3.43034 | M17: 3.14625 | N17: 2.8843548
A18: 8 | B18: 8 | C18: 7.7018785 | D18: 7.2390804 | E18: 6.7337145 | F18: 6.2103924 | G18: 5.6922672 | H18: 5.1981506 | I18: 4.7389543 | J18: 4.3187765 | K18: 3.9373126 | L18: 3.5918831 | M18: 3.2787858 | N18: 2.9940481
A19: 10 | B19: 10 | C19: 9.50464 | D19: 8.7725147 | E19: 7.9851813 | F19: 7.197758 | G19: 6.456834 | H19: 5.7867581 | I19: 5.1933727 | J19: 4.6723727 | K19: 4.2153623 | L19: 3.8131019 | M19: 3.4569163 | N19: 3.139194
... A22: 20 | B22: 20 | C22: 17.63785 | D22: 14.613515 | E22: 11.919518 | F22: 9.817745 | G22: 8.2281047 | H22: 7.0145241 | I22: 6.0679293 | J22: 5.3119812 | K22: 4.694679 | L22: 4.1802823 | M22: 3.7437969 | N22: 3.3673365
A25: Table 2: Pconesurface/Pinf
B26: 0 | C26: 2.5 | D26: 5 | E26: 7.5 | F26: 10 | G26: 12.5 | H26: 15 | I26: 17.5 | J26: 20 | K26: 22.5 | L26: 25 | M26: 27.5 | N26: 30
A27: 1.1 | B27: 1 | C27: 1.0097 | D27: 1.0406 | E27: 1.0966 | F27: 1.1552 | G27: 1.218
A28: 1.25 | B28: 1 | C28: 1.0128 | D28: 1.0488 | E28: 1.1096 | F28: 1.1748 | G28: 1.2458 | H28: 1.3224 | I28: 1.4047 | J28: 1.4918
A29: 1.5 | B29: 1 | C29: 1.0194326 | D29: 1.0624668 | E29: 1.1218836 | F29: 1.1949823 | G29: 1.2805338 | H29: 1.3780493 | I29: 1.4875334 | J29: 1.6094921 | K29: 1.7452173 | L29: 1.8977323
A30: 1.75 | B30: 1 | C30: 1.0245272 | D30: 1.0778796 | E30: 1.150982 | F30: 1.240679 | G30: 1.3455754 | H30: 1.4650276 | I30: 1.5987279 | J30: 1.7465521 | K30: 1.9085624 | L30: 2.0851453 | M30: 2.2773654 | N30: 2.4878749
A31: 2 | B31: 1 | C31: 1.0302014 | D31: 1.095048 | E31: 1.1836274 | F31: 1.2924832 | G31: 1.4202392 | H31: 1.5662549 | I31: 1.73013 | J31: 1.9114873 | K31: 2.1099574 | L31: 2.325245 | M31: 2.5572482 | N31: 2.8063347
A32: 2.5 | B32: 1 | C32: 1.0430034 | D32: 1.1338127 | E32: 1.2579479 | F32: 1.4118223 | G32: 1.5943908 | H32: 1.8051501 | I32: 2.0435503 | J32: 2.3088209 | K32: 2.5999833 | L32: 2.9158958 | M32: 3.2553311 | N32: 3.6170774
A33: 3 | B33: 1 | C33: 1.0575531 | D33: 1.1779135 | E33: 1.3434709 | F33: 1.5510936 | G33: 1.8002508 | H33: 2.0905385 | I33: 2.4211572 | J33: 2.7908532 | K33: 3.1979721 | L33: 3.6205103 | M33: 4.1162105 | N33: 4.6226939
A34: 3.5 | B34: 1 | C34: 1.07368 | D34: 1.2270211 | E34: 1.4399168 | F34: 1.7101603 | G34: 2.0377458 | H34: 2.4222429 | I34: 2.8624798 | J34: 3.3565631 | K34: 3.9019948 | L34: 4.4957647 | M34: 5.1344738 | N34: 5.8144615
A35: 4 | B35: 1 | C35: 1.091272 | D35: 1.2809867 | E35: 1.547292 | F35: 1.8892063 | G35: 2.3071757 | H35: 2.8006264 | I35: 3.3678429 | J35: 4.0061275 | K35: 4.7119593 | L35: 5.4811532 | M35: 6.3089994 | N35: 7.1904022
A36: 4.5 | B36: 1 | C36: 1.1102609 | D36: 1.3397531 | E36: 1.6656866 | F36: 2.0884875 | G36: 2.6089172 | H36: 3.2261054 | I36: 3.9376627 | J36: 4.7398834 | K36: 5.628081 | L36: 6.5967119 | M36: 7.6395491 | N36: 8.7499419
A37: 5 | B37: 1 | C37: 1.1205848 | D37: 1.403315 | E37: 1.7952468 | F37: 2.308246 | G37: 2.9432816 | H37: 3.6990542 | I37: 4.5722872 | J37: 5.558163 | K37: 6.6506071 | L37: 7.8425504 | M37: 9.1261264 | N37: 10.492909
A38: 6 | B38: 1 | C38: 1.1750571 | D38: 1.5449088 | E38: 2.0883718 | F38: 2.8100784 | G38: 3.7110158 | H38: 4.7885278 | I38: 6.0371455 | J38: 7.4492676 | K38: 9.0156074 | L38: 10.725597 | M38: 12.5675 | N38: 14.528819
A39: 7 | B39: 1 | C39: 1.2244683 | D39: 1.7060582 | E39: 2.427615 | F39: 3.3961384 | G39: 4.6121063 | H39: 6.0708563 | I39: 7.7641001 | J39: 9.6808592 | K39: 11.808092 | L39: 14.131046 | M39: 16.633476 | N39: 19.298175
A40: 8 | B40: 1 | C40: 1.2786974 | D40: 1.8871344 | E40: 2.8137638 | F40: 4.0673451 | G40: 5.6477433 | H40: 7.5471315 | I40: 9.7541022 | J40: 12.253764 | K40: 15.028693 | L40: 18.059352 | M40: 21.32435 | N40: 24.800936
A41: 10 | B41: 1 | C41: 1.4015141 | D41: 2.3102668 | E41: 3.7291669 | F41: 5.6691937 | G41: 8.1254669 | H41: 11.084206 | I41: 14.525483 | J41: 18.425183 | K41: 22.755513 | L41: 27.485425 | M41: 32.581175 | N41: 38.00706
... A44: 20 | B44: 1 | C44: 2.3107823 | D44: 3.6980529 | E44: 11.241661 | F44: 18.928672 | G44: 28.708667 | H44: 40.511555 | I44: 54.251895 | J44: 69.827597 | K44: 87.126234 | L44: 106.02202 | M44: 126.3799 | N44: 148.05417
A47: Table 5, CNa
A48: Mach Inf/Thetas | B48: 0 | C48: 2.5 | D48: 5 | E48: 7.5 | F48: 10 | G48: 12.5 | H48: 15 | I48: 17.5 | J48: 20 | K48: 22.5 | L48: 25 | M48: 27.5 | N48: 30
A49: 1.1 | B49: 2 | C49: 1.9781 | D49: 1.9437 | E49: 1.8875 | F49: 1.825 | G49: 1.7458
A50: 1.25 | B50: 2 | C50: 1.9711 | D50: 1.9417 | E50: 1.8875 | F50: 1.8333 | G50: 1.775 | H50: 1.7083 | I50: 1.6366 | J50: 1.575
...

Sheet nose profile

Sheet Cp distribution

Sheet SupersonicCalculations
A1: Supersonic Barrowman Equations | H1: 8 | I1: 9 | J1: 10 | K1: 11 | L1: 12 | M1: 13 | N1: 14 | O1: 15 | P1: 16 | Q1: 17 | R1: 18 | S1: 19 | T1: 20 | U1: 21 | V1: 22 | W1: 23 | X1: 24 | Y1: 25 | Z1: 26 | AA1: 27 | AB1: 28 | AC1: 29 | AD1: 30 | AE1: 31 | AF1: 32 | AG1: 33 | AH1: 34 | AI1: 35 | AJ1: 36 | AK1: 39 | AL1: 40 | AM1: 41 | AN1: 42 | AO1: 43 | AP1: 44 | AQ1: 45 | AR1: 46 | AS1: 47 | AT1: 48 | AU1: 49 | AV1: 50 | AW1: 51 | AX1: 52 | AY1: 53 | AZ1: 54 | BA1: 55
C2: dx | D2: =48.25/38 -> 1.2697368 | E2: in | F2: Pinf | G2: 14.68 | H2: psia | I2: Sref | J2: =PI()*(D5^2) -> 3.9760782 | K2: sq. in
C3: L | D3: =MAX(D14:D60) -> 55 | E3: in | F3: Mcone | G3: =((BILINTERP(inputtables!A4:N22,SupersonicCalculations!D7,SupersonicCalculations!D6))) -> #VALUE! | I3: Sb | J3: =J2 -> 3.9760782 | K3: sq in
A4: Cell Code | C4: D | D4: =2*MAX(E14:E60) -> 2.25 | E4: in | F4: Pcone/Pinf | G4: =BILINTERP(inputtables!A26:N44,SupersonicCalculations!D7,SupersonicCalculations!D6) -> #VALUE! | N4: Hemispherical Cap → | O4: pt/pinf | P4: pt, psia | Q4: Cptotal | R4: Rad, in | S4: thetaM, rad | T4: P1, psia | U4: dpds1 | V4: M1 | W4: Segment CDw | X4: Segment CNa, rad-1 | Y4: Segment Center of Pressure, in aft of nose tip
A5: Input | C5: R | D5: =D4/2 -> 1.125 | E5: in | F5: Pcone | G5: =G4*G2 -> #VALUE! | H5: psia | O5: =ptotalratio(D6,1.4) -> #VALUE! | P5: =O5*G2 -> #VALUE! | Q5: =cpt(D6,O5,1.4) -> #VALUE! | R5: =E14/SIN(PI()/2-ATAN((E15-E14)/(D15-D14))) -> 0.010426117 | S5: =PI()/2-ATAN((E15-E14)/(D15-D14)) -> 1.2839108 | T5: =P15 -> #VALUE! | U5: 0 | V5: =ROUNDDOWN(BILINTERP(inputtables!$A$4:$N$22,ABS(I14),D$6),8) -> #VALUE! | W5: =PI()*R5^2*(Q5/2)*(1-(COS(S5))^4)/J2 -> #VALUE! | X5: =PI()*R5^2*(Q5/2)*(SIN(S5))^4/J2 -> #VALUE! | Y5: =R5*PI()*(1-(4/5)*COS(S5)+(4/15)*COS(S5)*((SIN(S5))^2+2)/(SIN(S5)^4)-(8/15)*(SIN(S5))^4) -> 0.019084068
A6: Output | C6: Minf | D6: 1.6 | F6: fn | G6: =D3/D4 -> 24.444444
A7: Limitations | C7: cone angle | D7: =ROUNDDOWN(G15*180/PI(),5) -> 16.43729 | E7: degrees | F7: Minf/fn | G7: =D6/G6 -> 0.065454545 | O7: 1st Stage | S7: 2nd Stage
F8: qinf | G8: =(1.4*G$2*D$6^2)/2 -> 26.30656 | M8: 0 | N8: a | O8: Tip LE | P8: Subsonic LE | Q8: Tip LE | R8: e | S8: Tip LE | T8: Subsonic LE | U8: Tip LE | V8: e | W8: Minf
B9: Maximum Cone Half Angle for Supersonic Cone Surface Flow, rad | C9: Minimum Mach no. (Tip Interference) 1st Stage | D9: Maximum Mach no. (Subsonic Leading Edge) 1st Stage | E9: Minimum Mach no. (Sonic Leading Edge) 1st Stage | F9: Minimum Mach no. (Tip Interference) 2nd Stage | G9: Maximum Mach no. (Subsonic Leading Edge) 2nd Stage | H9: Minimum Mach no. (Sonic Leading Edge) 2nd Stage | I9: Maximum Wedge Half Angle for Supersonic Wedge Surface Flow 1st Stage, rad | J9: Maximum Wedge Half Angle for Supersonic Wedge Surface Flow 2nd Stage, rad | L9: No | M9: 0 | N9: 1 | O9: =C10 -> 1.2909944 | P9: =D10 -> 1.6666667 | Q9: =E10 -> 2.8480012 | R9: =IF(Q9+2<D6,D6+0.1,Q9+2) -> 4.8480012 | S9: =F10 -> 1.2247449 | T9: =G10 -> 1.9436506 | U9: =H10 -> 2.8480012 | V9: =IF(U9+2<D6,D6+0.1,U9+2) -> 4.8480012 | W9: 0.5
B10: =PI()*(D6^2-1)^1.5/(3.24*D6^3*(1-EXP(-5.5*(D6-1)))) -> 0.47890882 | C10: =SQRT(1+G64/(2*H64)) -> 1.2909944 | D10: =SQRT(1+1/(M64^2)) -> 1.6666667 | E10: =SQRT((F64/H64)^2+1) -> 2.8480012 | F10: =SQRT(1+G67/(2*H67)) -> 1.2247449 | G10: =SQRT(1+1/(M67^2)) -> 1.9436506 | H10: =SQRT((F67/H67)^2+1) -> 2.8480012 | I10: =Wedge_HalfAngle(D6,F64,G64,H64) -> #VALUE! | J10: =Wedge_HalfAngle(D6,F67,G67,H67) -> #VALUE! | L10: Yes | M10: 1 | N10: 1 | O10: =C10 -> 1.2909944 | P10: =D10 -> 1.6666667 | Q10: =E10 -> 2.8480012 | R10: =IF(Q10+2<D6,D6+0.1,Q10+2) -> 4.8480012 | S10: =F10 -> 1.2247449 | T10: =G10 -> 1.9436506 | U10: =H10 -> 2.8480012 | V10: =IF(U10+2<D6,D6+0.1,U10+2) -> 4.8480012 | W10: =D6 -> 1.6
B12: Body of Revolution → | C12: Element | D12: x, in | E12: r, in | F12: deltaR | G12: delta, rad | H12: ds | I12: deltadeg | J12: epsilon, flow deflection, rad | K12: Slender Body Theory | L12: M1 | M12: Wave type | N12: Pcone/Pinf | O12: P1 | P12: Pcone | Q12: nu1 | R12: nu2 | S12: M2 | T12: p1/p2 | U12: P2 | V12: beta1 | W12: beta2 | X12: omega1 | Y12: omega2 | Z12: dpds1 | AA12: dpds2 | AB12: eta@Pstation | AC12: P3 | AD12: dpds3 | AE12: p2/p3 | AF12: M3 | AG12: (P/Pinf) | AH12: xtan/L | AI12: Cp | AJ12: Segment CDw | AK12: Total Wave Drag, CDw | AN12: Mu1 | AO12: Mu2 | AP12: lambda1 | AQ12: lambda2 | AR12: CNalpha0 cone | AS12: Λ1 | AT12: Λ | AU12: Segment CNa, rad-1 | AV12: Total Cnalpha, CNa, rad-1 | AW12: Segment CMalpha about x = 0 | AX12: Segment Center of Pressure, in aft of nose tip | AY12: Total Cmalpha, CMa, about x = 0 | AZ12: Main Body Center of Pressure, in | BB12: Vehicle CNα/rad | BC12: Vehicle Center of Pressure, in
C14: 0 | D14: 0 | E14: 0.01 | F14: If r > 0 then Tangent Hemispherical Cap is fitted ← | G14: =IF(E14>0,G15,0) -> 0.286885 | I14: =IF(E14>0,ROUNDDOWN(G14*180/PI(),8),0) -> 16.4373 | AJ14: =W5 -> #VALUE! | AK14: =SUM(AJ14:AJ61) -> #VALUE! | AU14: =X5 -> #VALUE! | AV14: =SUM(AU14:AU60) -> #VALUE! | AW14: =-X5*Y5/D4 -> #VALUE! | AX14: =Y5 -> 0.019084068 | AY14: =SUM(AW14:AW60) -> #VALUE! | AZ14: =-AY14/AV14*D$4 -> #VALUE! | BB14: =IF(B64=1,AV14+AE64,AV14+AE64+AE67+AW64+AX64) -> #VALUE! | BC14: =IF(B64=1,AV14*AZ14+AE64*AJ64,AV14*AZ14+AE64*AJ64+AE67*AJ67+AW64*AJ64+AX64*AG64)/BB14 -> #VALUE!
C15: =C14+1 -> 1 | D15: 0.5 | E15: 0.15751205 | F15: =(E15-E14) -> 0.14751205 | G15: =ROUNDDOWN(ATAN(F15/(D15-D14)),6) -> 0.286885 | H15: =IF(G15>0,F15/SIN(G15),D15-D14) -> 0.52130678 | I15: =ROUNDDOWN(G15*180/PI(),8) -> 16.4373 | J15: =ROUNDDOWN(epsilonangle(G14,G15),8) -> #VALUE! | K15: =IF($G$15>$B$10,TRUE(),FALSE()) -> 0 | L15: =G3 -> #VALUE! | M15: =IF(G15>G16,"Expansion",IF(G15=G16,"No Change","Compression")) -> Expansion | N15: =ROUNDDOWN(BILINTERP(inputtables!$A$26:$N$44,ABS(I15),D$6),8) -> #VALUE! | O15: =G2*G4 -> #VALUE! | P15: =N15*G$2 -> #VALUE! | S15: =G3 -> #VALUE! | T15: =p1p2(L15,S15,1.4) -> #VALUE! | U15: =P15 -> #VALUE! | V15: =(1.4*O15*L15^2)/(2*(L15^2-1)) -> #VALUE! | W15: =(1.4*U15*S15^2)/(2*(S15^2-1)) -> #VALUE! | Z15: 0 | AA15: =0 -> 0 | AB15: =0 -> 0 | AC15: =ROUNDDOWN(Pmainval(P15,U15,AB15),8) -> #VALUE! | AD15: =0 -> 0 | AE15: 1 | AF15: =S15 -> #VALUE! | AG15: =AC15/G$2 -> #VALUE! | AH15: 0 | AI15: =(2/(1.4*D$6^2))*(AG15-1) -> #VALUE! | AJ15: =drag(D14,D15,E14,E15,G15,P15,U15,AB15,AA15) -> #VALUE! | AN15: =ASIN(1/L15) -> #VALUE! | AO15: =ASIN(1/S15) -> #VALUE! | AP15: =2*1.4*O15/SIN(2*AN15) -> #VALUE! | AQ15: =2*1.4*U15/SIN(2*AO15) -> #VALUE! | AR15: =ROUNDDOWN(BILINTERP(inputtables!$A$48:$N$66,ABS(I15),D$6),8) -> #VALUE! | AS15: =AT15 -> #VALUE! | AT15: =TAN(D7*PI()/180)*AR15 -> #VALUE! | AU15: =IF(K15=TRUE(),Segment_Cnalpha(E14,E15,$J$2),cnalpha(D14,D15,E14,E15,G15,P15,U15,AB15,AA15,AP15,AQ15,AS15,AR15,J$3)) -> #VALUE! | AW15: =IF(K15=TRUE(),Segment_CMalpha(AU15,AX15),cmalpha1(D14,D15,E14,E15,G15,P15,U15,AB15,AA15,AP15,AQ15,AS15,AR15,J$3,D$4)) -> #VALUE! | AX15: =IF(K15=TRUE(),Segment_CP(D14,D15,E14,E15),-$D$4*AW15/AU15) -> #VALUE!
C16: =C15+1 -> 2 | D16: 1 | E16: 0.2611451 | F16: =(E16-E15) -> 0.10363305 | G16: =ROUNDDOWN(ATAN(F16/(D16-D15)),6) -> 0.204372 | H16: =IF(G16>0,F16/SIN(G16),D16-D15) -> 0.51062771 | I16: =ROUNDDOWN(G16*180/PI(),8) -> 11.709653 | J16: =ROUNDDOWN(epsilonangle(G15,G16),8) -> #VALUE! | K16: =IF(K15=TRUE(),TRUE(),IF(M16="Compression",IF(G16>(0.3208*(L16^2-1)^(3/2)/L16^2),TRUE(),FALSE()),FALSE())) -> 0 | L16: =IF(ISERROR(AF15),L15,AF15) -> #VALUE! | M16: =IF(G16>G17,"Expansion",IF(G16=G17,"No Change","Compression")) -> Expansion | N16: =ROUNDDOWN(BILINTERP(inputtables!$A$26:$N$44,ABS(I16),D$6),8) -> #VALUE! | O16: =AC15 -> #VALUE! | P16: =N16*G$2 -> #VALUE! | Q16: =nu(L16,1.4) -> #VALUE! | R16: =IF(M16="Expansion",Q16+ABS(J16),IF(M16="Compression",Q16-ABS(J16),Q16)) -> #VALUE! | S16: =IF(I15>=I16,ROUNDDOWN((newtonmethod(L16,R16)),6),ROUNDDOWN(M2oblique(L16,J16,1.4),6)) -> #VALUE! | T16: =IF(I15>=I16,p1p2(L16,S16,1.4),p1p2oblique(L16,J16,1.4)) -> #VALUE! | U16: =ROUNDDOWN((1/T16)*O16,6) -> #VALUE! | V16: =(1.4*O16*L16^2)/(2*(L16^2-1)) -> #VALUE! | W16: =(1.4*U16*S16^2)/(2*(S16^2-1)) -> #VALUE! | X16: =omega(L16,1.4) -> #VALUE! | Y16: =omega(S16,1.4) -> #VALUE! | Z16: =AD15 -> 0 | AA16: =(dpds2(1.4,J16,L16,S16,O16,U16,V16,W16,E15,X16,Y16,G15,G16,Z16)) -> #VALUE! | AB16: =(eta(AA16,P16,U16,G16,D15,D16)) -> #VALUE! | AC16: =ROUNDDOWN(Pmainval(P16,U16,AB16),8) -> #VALUE! | AD16: =((dpds3(P16,U16,AC16,AA16))) -> #VALUE! | AE16: =U16/AC16 -> #VALUE! | AF16: =ROUNDDOWN((Machfinder(AE16,S16,1.4)),6) -> #VALUE! | AG16: =AC16/G$2 -> #VALUE! | AH16: =D16/D$3 -> 0.018181818 | AI16: =(2/(1.4*D$6^2))*(AG16-1) -> #VALUE! | AJ16: =IF(K16=FALSE(),drag(D15,D16,E15,E16,G16,P16,U16,AB16,AA16),0) -> #VALUE! | AN16: =ASIN(1/L16) -> #VALUE! | AO16: =ASIN(1/S16) -> #VALUE! | AP16: =2*1.4*O16/SIN(2*AN16) -> #VALUE! | AQ16: =2*1.4*U16/SIN(2*AO16) -> #VALUE! | AR16: =ROUNDDOWN(BILINTERP(inputtables!$A$48:$N$66,ABS(I16),D$6),8) -> #VALUE! | AS16: =AT15 -> #VALUE! | AT16: =DeltaL(M$16:M16,U16,O16,J16,M16,L16,1.4,AB16,G16,AR16,AP16,AQ16,AS16) -> #VALUE! | AU16: =IF(K16=TRUE(),Segment_Cnalpha(E15,E16,$J$2),cnalpha(D15,D16,E15,E16,G16,P16,U16,AB16,AA16,AP16,AQ16,AS16,AR16,J$3)) -> #VALUE! | AW16: =IF(K16=TRUE(),Segment_CMalpha(AU16,AX16),cmalpha1(D15,D16,E15,E16,G16,P16,U16,AB16,AA16,AP16,AQ16,AS16,AR16,J$3,D$4)) -> #VALUE! | AX16: =IF(K16=TRUE(),Segment_CP(D15,D16,E15,E16),-$D$4*AW16/AU16) -> #VALUE!
C17: =C16+1 -> 3 | D17: 1.5 | E17: 0.34883933 | F17: =(E17-E16) -> 0.087694235 | G17: =ROUNDDOWN(ATAN(F17/(D17-D16)),6) -> 0.173622 | H17: =IF(G17>0,F17/SIN(G17),D17-D16) -> 0.50763368 | I17: =ROUNDDOWN(G17*180/PI(),8) -> 9.9478078 | J17: =ROUNDDOWN(epsilonangle(G16,G17),8) -> #VALUE! | K17: =IF(K16=TRUE(),TRUE(),IF(M17="Compression",IF(G17>(0.3208*(L17^2-1)^(3/2)/L17^2),TRUE(),FALSE()),FALSE())) -> 0 | L17: =IF(ISERROR(AF16),L16,AF16) -> #VALUE! | M17: =IF(G17>G18,"Expansion",IF(G17=G18,"No Change","Compression")) -> Expansion | N17: =ROUNDDOWN(BILINTERP(inputtables!$A$26:$N$44,ABS(I17),D$6),8) -> #VALUE! | O17: =AC16 -> #VALUE! | P17: =N17*G$2 -> #VALUE! | Q17: =nu(L17,1.4) -> #VALUE! | R17: =IF(M17="Expansion",Q17+ABS(J17),IF(M17="Compression",Q17-ABS(J17),Q17)) -> #VALUE! | S17: =IF(I16>=I17,ROUNDDOWN((newtonmethod(L17,R17)),6),ROUNDDOWN(M2oblique(L17,J17,1.4),6)) -> #VALUE! | T17: =IF(I16>=I17,p1p2(L17,S17,1.4),p1p2oblique(L17,J17,1.4)) -> #VALUE! | U17: =ROUNDDOWN((1/T17)*O17,6) -> #VALUE! | V17: =(1.4*O17*L17^2)/(2*(L17^2-1)) -> #VALUE! | W17: =(1.4*U17*S17^2)/(2*(S17^2-1)) -> #VALUE! | X17: =omega(L17,1.4) -> #VALUE! | Y17: =omega(S17,1.4) -> #VALUE! | Z17: =AD16 -> #VALUE! | AA17: =(dpds2(1.4,J17,L17,S17,O17,U17,V17,W17,E16,X17,Y17,G16,G17,Z17)) -> #VALUE! | AB17: =(eta(AA17,P17,U17,G17,D16,D17)) -> #VALUE! | AC17: =ROUNDDOWN(Pmainval(P17,U17,AB17),8) -> #VALUE! | AD17: =((dpds3(P17,U17,AC17,AA17))) -> #VALUE! | AE17: =U17/AC17 -> #VALUE! | AF17: =ROUNDDOWN((Machfinder(AE17,S17,1.4)),6) -> #VALUE! | AG17: =AC17/G$2 -> #VALUE! | AH17: =D17/D$3 -> 0.027272727 | AI17: =(2/(1.4*D$6^2))*(AG17-1) -> #VALUE! | AJ17: =IF(K17=FALSE(),drag(D16,D17,E16,E17,G17,P17,U17,AB17,AA17),0) -> #VALUE! | AN17: =ASIN(1/L17) -> #VALUE! | AO17: =ASIN(1/S17) -> #VALUE! | AP17: =2*1.4*O17/SIN(2*AN17) -> #VALUE! | AQ17: =2*1.4*U17/SIN(2*AO17) -> #VALUE! | AR17: =ROUNDDOWN(BILINTERP(inputtables!$A$48:$N$66,ABS(I17),D$6),8) -> #VALUE! | AS17: =AT16 -> #VALUE! | AT17: =DeltaL(M$16:M17,U17,O17,J17,M17,L17,1.4,AB17,G17,AR17,AP17,AQ17,AS17) -> #VALUE! | AU17: =IF(K17=TRUE(),Segment_Cnalpha(E16,E17,$J$2),cnalpha(D16,D17,E16,E17,G17,P17,U17,AB17,AA17,AP17,AQ17,AS17,AR17,J$3)) -> #VALUE! | AW17: =IF(K17=TRUE(),Segment_CMalpha(AU17,AX17),cmalpha1(D16,D17,E16,E17,G17,P17,U17,AB17,AA17,AP17,AQ17,AS17,AR17,J$3,D$4)) -> #VALUE! | AX17: =IF(K17=TRUE(),Segment_CP(D16,D17,E16,E17),-$D$4*AW17/AU17) -> #VALUE!
C18: =C17+1 -> 4 | D18: 2 | E18: 0.42646105 | F18: =(E18-E17) -> 0.077621716 | G18: =ROUNDDOWN(ATAN(F18/(D18-D17)),6) -> 0.154014 | H18: =IF(G18>0,F18/SIN(G18),D18-D17) -> 0.5059893 | I18: =ROUNDDOWN(G18*180/PI(),8) -> 8.8243522 | J18: =ROUNDDOWN(epsilonangle(G17,G18),8) -> #VALUE! | K18: =IF(K17=TRUE(),TRUE(),IF(M18="Compression",IF(G18>(0.3208*(L18^2-1)^(3/2)/L18^2),TRUE(),FALSE()),FALSE())) -> 0 | L18: =IF(ISERROR(AF17),L17,AF17) -> #VALUE! | M18: =IF(G18>G19,"Expansion",IF(G18=G19,"No Change","Compression")) -> Expansion | N18: =ROUNDDOWN(BILINTERP(inputtables!$A$26:$N$44,ABS(I18),D$6),8) -> #VALUE! | O18: =AC17 -> #VALUE! | P18: =N18*G$2 -> #VALUE! | Q18: =nu(L18,1.4) -> #VALUE! | R18: =IF(M18="Expansion",Q18+ABS(J18),IF(M18="Compression",Q18-ABS(J18),Q18)) -> #VALUE! | S18: =IF(I17>=I18,ROUNDDOWN((newtonmethod(L18,R18)),6),ROUNDDOWN(M2oblique(L18,J18,1.4),6)) -> #VALUE! | T18: =IF(I17>=I18,p1p2(L18,S18,1.4),p1p2oblique(L18,J18,1.4)) -> #VALUE! | U18: =ROUNDDOWN((1/T18)*O18,6) -> #VALUE! | V18: =(1.4*O18*L18^2)/(2*(L18^2-1)) -> #VALUE! | W18: =(1.4*U18*S18^2)/(2*(S18^2-1)) -> #VALUE! | X18: =omega(L18,1.4) -> #VALUE! | Y18: =omega(S18,1.4) -> #VALUE! | Z18: =AD17 -> #VALUE! | AA18: =(dpds2(1.4,J18,L18,S18,O18,U18,V18,W18,E17,X18,Y18,G17,G18,Z18)) -> #VALUE! | AB18: =(eta(AA18,P18,U18,G18,D17,D18)) -> #VALUE! | AC18: =ROUNDDOWN(Pmainval(P18,U18,AB18),8) -> #VALUE! | AD18: =((dpds3(P18,U18,AC18,AA18))) -> #VALUE! | AE18: =U18/AC18 -> #VALUE! | AF18: =ROUNDDOWN((Machfinder(AE18,S18,1.4)),6) -> #VALUE! | AG18: =AC18/G$2 -> #VALUE! | AH18: =D18/D$3 -> 0.036363636 | AI18: =(2/(1.4*D$6^2))*(AG18-1) -> #VALUE! | AJ18: =IF(K18=FALSE(),drag(D17,D18,E17,E18,G18,P18,U18,AB18,AA18),0) -> #VALUE! | AN18: =ASIN(1/L18) -> #VALUE! | AO18: =ASIN(1/S18) -> #VALUE! | AP18: =2*1.4*O18/SIN(2*AN18) -> #VALUE! | AQ18: =2*1.4*U18/SIN(2*AO18) -> #VALUE! | AR18: =ROUNDDOWN(BILINTERP(inputtables!$A$48:$N$66,ABS(I18),D$6),8) -> #VALUE! | AS18: =AT17 -> #VALUE! | AT18: =DeltaL(M$16:M18,U18,O18,J18,M18,L18,1.4,AB18,G18,AR18,AP18,AQ18,AS18) -> #VALUE! | AU18: =IF(K18=TRUE(),Segment_Cnalpha(E17,E18,$J$2),cnalpha(D17,D18,E17,E18,G18,P18,U18,AB18,AA18,AP18,AQ18,AS18,AR18,J$3)) -> #VALUE! | AW18: =IF(K18=TRUE(),Segment_CMalpha(AU18,AX18),cmalpha1(D17,D18,E17,E18,G18,P18,U18,AB18,AA18,AP18,AQ18,AS18,AR18,J$3,D$4)) -> #VALUE! | AX18: =IF(K18=TRUE(),Segment_CP(D17,D18,E17,E18),-$D$4*AW18/AU18) -> #VALUE!
C19: =C18+1 -> 5 | D19: 2.5 | E19: 0.4965711 | F19: =(E19-E18) -> 0.070110048 | G19: =ROUNDDOWN(ATAN(F19/(D19-D18)),6) -> 0.139311 | H19: =IF(G19>0,F19/SIN(G19),D19-D18) -> 0.50489437 | I19: =ROUNDDOWN(G19*180/PI(),8) -> 7.9819323 | J19: =ROUNDDOWN(epsilonangle(G18,G19),8) -> #VALUE! | K19: =IF(K18=TRUE(),TRUE(),IF(M19="Compression",IF(G19>(0.3208*(L19^2-1)^(3/2)/L19^2),TRUE(),FALSE()),FALSE())) -> 0 | L19: =IF(ISERROR(AF18),L18,AF18) -> #VALUE! | M19: =IF(G19>G20,"Expansion",IF(G19=G20,"No Change","Compression")) -> Expansion | N19: =ROUNDDOWN(BILINTERP(inputtables!$A$26:$N$44,ABS(I19),D$6),8) -> #VALUE! | O19: =AC18 -> #VALUE! | P19: =N19*G$2 -> #VALUE! | Q19: =nu(L19,1.4) -> #VALUE! | R19: =IF(M19="Expansion",Q19+ABS(J19),IF(M19="Compression",Q19-ABS(J19),Q19)) -> #VALUE! | S19: =IF(I18>=I19,ROUNDDOWN((newtonmethod(L19,R19)),6),ROUNDDOWN(M2oblique(L19,J19,1.4),6)) -> #VALUE! | T19: =IF(I18>=I19,p1p2(L19,S19,1.4),p1p2oblique(L19,J19,1.4)) -> #VALUE! | U19: =ROUNDDOWN((1/T19)*O19,6) -> #VALUE! | V19: =(1.4*O19*L19^2)/(2*(L19^2-1)) -> #VALUE! | W19: =(1.4*U19*S19^2)/(2*(S19^2-1)) -> #VALUE! | X19: =omega(L19,1.4) -> #VALUE! | Y19: =omega(S19,1.4) -> #VALUE! | Z19: =AD18 -> #VALUE! | AA19: =(dpds2(1.4,J19,L19,S19,O19,U19,V19,W19,E18,X19,Y19,G18,G19,Z19)) -> #VALUE! | AB19: =(eta(AA19,P19,U19,G19,D18,D19)) -> #VALUE! | AC19: =ROUNDDOWN(Pmainval(P19,U19,AB19),8) -> #VALUE! | AD19: =((dpds3(P19,U19,AC19,AA19))) -> #VALUE! | AE19: =U19/AC19 -> #VALUE! | AF19: =ROUNDDOWN((Machfinder(AE19,S19,1.4)),6) -> #VALUE! | AG19: =AC19/G$2 -> #VALUE! | AH19: =D19/D$3 -> 0.045454545 | AI19: =(2/(1.4*D$6^2))*(AG19-1) -> #VALUE! | AJ19: =IF(K19=FALSE(),drag(D18,D19,E18,E19,G19,P19,U19,AB19,AA19),0) -> #VALUE! | AN19: =ASIN(1/L19) -> #VALUE! | AO19: =ASIN(1/S19) -> #VALUE! | AP19: =2*1.4*O19/SIN(2*AN19) -> #VALUE! | AQ19: =2*1.4*U19/SIN(2*AO19) -> #VALUE! | AR19: =ROUNDDOWN(BILINTERP(inputtables!$A$48:$N$66,ABS(I19),D$6),8) -> #VALUE! | AS19: =AT18 -> #VALUE! | AT19: =DeltaL(M$16:M19,U19,O19,J19,M19,L19,1.4,AB19,G19,AR19,AP19,AQ19,AS19) -> #VALUE! | AU19: =IF(K19=TRUE(),Segment_Cnalpha(E18,E19,$J$2),cnalpha(D18,D19,E18,E19,G19,P19,U19,AB19,AA19,AP19,AQ19,AS19,AR19,J$3)) -> #VALUE! | AW19: =IF(K19=TRUE(),Segment_CMalpha(AU19,AX19),cmalpha1(D18,D19,E18,E19,G19,P19,U19,AB19,AA19,AP19,AQ19,AS19,AR19,J$3,D$4)) -> #VALUE! | AX19: =IF(K19=TRUE(),Segment_CP(D18,D19,E18,E19),-$D$4*AW19/AU19) -> #VALUE!
C20: =C19+1 -> 6 | D20: 3 | E20: 0.56059761 | F20: =(E20-E19) -> 0.064026511 | G20: =ROUNDDOWN(ATAN(F20/(D20-D19)),6) -> 0.127359 | H20: =IF(G20>0,F20/SIN(G20),D20-D19) -> 0.5040863 | I20: =ROUNDDOWN(G20*180/PI(),8) -> 7.2971332 | J20: =ROUNDDOWN(epsilonangle(G19,G20),8) -> #VALUE! | K20: =IF(K19=TRUE(),TRUE(),IF(M20="Compression",IF(G20>(0.3208*(L20^2-1)^(3/2)/L20^2),TRUE(),FALSE()),FALSE())) -> 0 | L20: =IF(ISERROR(AF19),L19,AF19) -> #VALUE! | M20: =IF(G20>G21,"Expansion",IF(G20=G21,"No Change","Compression")) -> Expansion | N20: =ROUNDDOWN(BILINTERP(inputtables!$A$26:$N$44,ABS(I20),D$6),8) -> #VALUE! | O20: =AC19 -> #VALUE! | P20: =N20*G$2 -> #VALUE! | Q20: =nu(L20,1.4) -> #VALUE! | R20: =IF(M20="Expansion",Q20+ABS(J20),IF(M20="Compression",Q20-ABS(J20),Q20)) -> #VALUE! | S20: =IF(I19>=I20,ROUNDDOWN((newtonmethod(L20,R20)),6),ROUNDDOWN(M2oblique(L20,J20,1.4),6)) -> #VALUE! | T20: =IF(I19>=I20,p1p2(L20,S20,1.4),p1p2oblique(L20,J20,1.4)) -> #VALUE! | U20: =ROUNDDOWN((1/T20)*O20,6) -> #VALUE! | V20: =(1.4*O20*L20^2)/(2*(L20^2-1)) -> #VALUE! | W20: =(1.4*U20*S20^2)/(2*(S20^2-1)) -> #VALUE! | X20: =omega(L20,1.4) -> #VALUE! | Y20: =omega(S20,1.4) -> #VALUE! | Z20: =AD19 -> #VALUE! | AA20: =(dpds2(1.4,J20,L20,S20,O20,U20,V20,W20,E19,X20,Y20,G19,G20,Z20)) -> #VALUE! | AB20: =(eta(AA20,P20,U20,G20,D19,D20)) -> #VALUE! | AC20: =ROUNDDOWN(Pmainval(P20,U20,AB20),8) -> #VALUE! | AD20: =((dpds3(P20,U20,AC20,AA20))) -> #VALUE! | AE20: =U20/AC20 -> #VALUE! | AF20: =ROUNDDOWN((Machfinder(AE20,S20,1.4)),6) -> #VALUE! | AG20: =AC20/G$2 -> #VALUE! | AH20: =D20/D$3 -> 0.054545455 | AI20: =(2/(1.4*D$6^2))*(AG20-1) -> #VALUE! | AJ20: =IF(K20=FALSE(),drag(D19,D20,E19,E20,G20,P20,U20,AB20,AA20),0) -> #VALUE! | AN20: =ASIN(1/L20) -> #VALUE! | AO20: =ASIN(1/S20) -> #VALUE! | AP20: =2*1.4*O20/SIN(2*AN20) -> #VALUE! | AQ20: =2*1.4*U20/SIN(2*AO20) -> #VALUE! | AR20: =ROUNDDOWN(BILINTERP(inputtables!$A$48:$N$66,ABS(I20),D$6),8) -> #VALUE! | AS20: =AT19 -> #VALUE! | AT20: =DeltaL(M$16:M20,U20,O20,J20,M20,L20,1.4,AB20,G20,AR20,AP20,AQ20,AS20) -> #VALUE! | AU20: =IF(K20=TRUE(),Segment_Cnalpha(E19,E20,$J$2),cnalpha(D19,D20,E19,E20,G20,P20,U20,AB20,AA20,AP20,AQ20,AS20,AR20,J$3)) -> #VALUE! | AW20: =IF(K20=TRUE(),Segment_CMalpha(AU20,AX20),cmalpha1(D19,D20,E19,E20,G20,P20,U20,AB20,AA20,AP20,AQ20,AS20,AR20,J$3,D$4)) -> #VALUE! | AX20: =IF(K20=TRUE(),Segment_CP(D19,D20,E19,E20),-$D$4*AW20/AU20) -> #VALUE!
C21: =C20+1 -> 7 | D21: 3.5 | E21: 0.6194465 | F21: =(E21-E20) -> 0.058848885 | G21: =ROUNDDOWN(ATAN(F21/(D21-D20)),6) -> 0.117158 | H21: =IF(G21>0,F21/SIN(G21),D21-D20) -> 0.50345454 | I21: =ROUNDDOWN(G21*180/PI(),8) -> 6.7126589 | J21: =ROUNDDOWN(epsilonangle(G20,G21),8) -> #VALUE! | K21: =IF(K20=TRUE(),TRUE(),IF(M21="Compression",IF(G21>(0.3208*(L21^2-1)^(3/2)/L21^2),TRUE(),FALSE()),FALSE())) -> 0 | L21: =IF(ISERROR(AF20),L20,AF20) -> #VALUE! | M21: =IF(G21>G22,"Expansion",IF(G21=G22,"No Change","Compression")) -> Expansion | N21: =ROUNDDOWN(BILINTERP(inputtables!$A$26:$N$44,ABS(I21),D$6),8) -> #VALUE! | O21: =AC20 -> #VALUE! | P21: =N21*G$2 -> #VALUE! | Q21: =nu(L21,1.4) -> #VALUE! | R21: =IF(M21="Expansion",Q21+ABS(J21),IF(M21="Compression",Q21-ABS(J21),Q21)) -> #VALUE! | S21: =IF(I20>=I21,ROUNDDOWN((newtonmethod(L21,R21)),6),ROUNDDOWN(M2oblique(L21,J21,1.4),6)) -> #VALUE! | T21: =IF(I20>=I21,p1p2(L21,S21,1.4),p1p2oblique(L21,J21,1.4)) -> #VALUE! | U21: =ROUNDDOWN((1/T21)*O21,6) -> #VALUE! | V21: =(1.4*O21*L21^2)/(2*(L21^2-1)) -> #VALUE! | W21: =(1.4*U21*S21^2)/(2*(S21^2-1)) -> #VALUE! | X21: =omega(L21,1.4) -> #VALUE! | Y21: =omega(S21,1.4) -> #VALUE! | Z21: =AD20 -> #VALUE! | AA21: =(dpds2(1.4,J21,L21,S21,O21,U21,V21,W21,E20,X21,Y21,G20,G21,Z21)) -> #VALUE! | AB21: =(eta(AA21,P21,U21,G21,D20,D21)) -> #VALUE! | AC21: =ROUNDDOWN(Pmainval(P21,U21,AB21),8) -> #VALUE! | AD21: =((dpds3(P21,U21,AC21,AA21))) -> #VALUE! | AE21: =U21/AC21 -> #VALUE! | AF21: =ROUNDDOWN((Machfinder(AE21,S21,1.4)),6) -> #VALUE! | AG21: =AC21/G$2 -> #VALUE! | AH21: =D21/D$3 -> 0.063636364 | AI21: =(2/(1.4*D$6^2))*(AG21-1) -> #VALUE! | AJ21: =IF(K21=FALSE(),drag(D20,D21,E20,E21,G21,P21,U21,AB21,AA21),0) -> #VALUE! | AN21: =ASIN(1/L21) -> #VALUE! | AO21: =ASIN(1/S21) -> #VALUE! | AP21: =2*1.4*O21/SIN(2*AN21) -> #VALUE! | AQ21: =2*1.4*U21/SIN(2*AO21) -> #VALUE! | AR21: =ROUNDDOWN(BILINTERP(inputtables!$A$48:$N$66,ABS(I21),D$6),8) -> #VALUE! | AS21: =AT20 -> #VALUE! | AT21: =DeltaL(M$16:M21,U21,O21,J21,M21,L21,1.4,AB21,G21,AR21,AP21,AQ21,AS21) -> #VALUE! | AU21: =IF(K21=TRUE(),Segment_Cnalpha(E20,E21,$J$2),cnalpha(D20,D21,E20,E21,G21,P21,U21,AB21,AA21,AP21,AQ21,AS21,AR21,J$3)) -> #VALUE! | AW21: =IF(K21=TRUE(),Segment_CMalpha(AU21,AX21),cmalpha1(D20,D21,E20,E21,G21,P21,U21,AB21,AA21,AP21,AQ21,AS21,AR21,J$3,D$4)) -> #VALUE! | AX21: =IF(K21=TRUE(),Segment_CP(D20,D21,E20,E21),-$D$4*AW21/AU21) -> #VALUE!
C22: =C21+1 -> 8 | D22: 4 | E22: 0.67374063 | F22: =(E22-E21) -> 0.054294138 | G22: =ROUNDDOWN(ATAN(F22/(D22-D21)),6) -> 0.108164 | H22: =IF(G22>0,F22/SIN(G22),D22-D21) -> 0.50294138 | I22: =ROUNDDOWN(G22*180/PI(),8) -> 6.1973407 | J22: =ROUNDDOWN(epsilonangle(G21,G22),8) -> #VALUE! | K22: =IF(K21=TRUE(),TRUE(),IF(M22="Compression",IF(G22>(0.3208*(L22^2-1)^(3/2)/L22^2),TRUE(),FALSE()),FALSE())) -> 0 | L22: =IF(ISERROR(AF21),L21,AF21) -> #VALUE! | M22: =IF(G22>G23,"Expansion",IF(G22=G23,"No Change","Compression")) -> Expansion | N22: =ROUNDDOWN(BILINTERP(inputtables!$A$26:$N$44,ABS(I22),D$6),8) -> #VALUE! | O22: =AC21 -> #VALUE! | P22: =N22*G$2 -> #VALUE! | Q22: =nu(L22,1.4) -> #VALUE! | R22: =IF(M22="Expansion",Q22+ABS(J22),IF(M22="Compression",Q22-ABS(J22),Q22)) -> #VALUE! | S22: =IF(I21>=I22,ROUNDDOWN((newtonmethod(L22,R22)),6),ROUNDDOWN(M2oblique(L22,J22,1.4),6)) -> #VALUE! | T22: =IF(I21>=I22,p1p2(L22,S22,1.4),p1p2oblique(L22,J22,1.4)) -> #VALUE! | U22: =ROUNDDOWN((1/T22)*O22,6) -> #VALUE! | V22: =(1.4*O22*L22^2)/(2*(L22^2-1)) -> #VALUE! | W22: =(1.4*U22*S22^2)/(2*(S22^2-1)) -> #VALUE! | X22: =omega(L22,1.4) -> #VALUE! | Y22: =omega(S22,1.4) -> #VALUE! | Z22: =AD21 -> #VALUE! | AA22: =(dpds2(1.4,J22,L22,S22,O22,U22,V22,W22,E21,X22,Y22,G21,G22,Z22)) -> #VALUE! | AB22: =(eta(AA22,P22,U22,G22,D21,D22)) -> #VALUE! | AC22: =ROUNDDOWN(Pmainval(P22,U22,AB22),8) -> #VALUE! | AD22: =((dpds3(P22,U22,AC22,AA22))) -> #VALUE! | AE22: =U22/AC22 -> #VALUE! | AF22: =ROUNDDOWN((Machfinder(AE22,S22,1.4)),6) -> #VALUE! | AG22: =AC22/G$2 -> #VALUE! | AH22: =D22/D$3 -> 0.072727273 | AI22: =(2/(1.4*D$6^2))*(AG22-1) -> #VALUE! | AJ22: =IF(K22=FALSE(),drag(D21,D22,E21,E22,G22,P22,U22,AB22,AA22),0) -> #VALUE! | AN22: =ASIN(1/L22) -> #VALUE! | AO22: =ASIN(1/S22) -> #VALUE! | AP22: =2*1.4*O22/SIN(2*AN22) -> #VALUE! | AQ22: =2*1.4*U22/SIN(2*AO22) -> #VALUE! | AR22: =ROUNDDOWN(BILINTERP(inputtables!$A$48:$N$66,ABS(I22),D$6),8) -> #VALUE! | AS22: =AT21 -> #VALUE! | AT22: =DeltaL(M$16:M22,U22,O22,J22,M22,L22,1.4,AB22,G22,AR22,AP22,AQ22,AS22) -> #VALUE! | AU22: =IF(K22=TRUE(),Segment_Cnalpha(E21,E22,$J$2),cnalpha(D21,D22,E21,E22,G22,P22,U22,AB22,AA22,AP22,AQ22,AS22,AR22,J$3)) -> #VALUE! | AW22: =IF(K22=TRUE(),Segment_CMalpha(AU22,AX22),cmalpha1(D21,D22,E21,E22,G22,P22,U22,AB22,AA22,AP22,AQ22,AS22,AR22,J$3,D$4)) -> #VALUE! | AX22: =IF(K22=TRUE(),Segment_CP(D21,D22,E21,E22),-$D$4*AW22/AU22) -> #VALUE!
C23: =C22+1 -> 9 | D23: 4.5 | E23: 0.72393262 | F23: =(E23-E22) -> 0.050191983 | G23: =ROUNDDOWN(ATAN(F23/(D23-D22)),6) -> 0.100048 | H23: =IF(G23>0,F23/SIN(G23),D23-D22) -> 0.50251694 | I23: =ROUNDDOWN(G23*180/PI(),8) -> 5.7323281 | J23: =ROUNDDOWN(epsilonangle(G22,G23),8) -> #VALUE! | K23: =IF(K22=TRUE(),TRUE(),IF(M23="Compression",IF(G23>(0.3208*(L23^2-1)^(3/2)/L23^2),TRUE(),FALSE()),FALSE())) -> 0 | L23: =IF(ISERROR(AF22),L22,AF22) -> #VALUE! | M23: =IF(G23>G24,"Expansion",IF(G23=G24,"No Change","Compression")) -> Expansion | N23: =ROUNDDOWN(BILINTERP(inputtables!$A$26:$N$44,ABS(I23),D$6),8) -> #VALUE! | O23: =AC22 -> #VALUE! | P23: =N23*G$2 -> #VALUE! | Q23: =nu(L23,1.4) -> #VALUE! | R23: =IF(M23="Expansion",Q23+ABS(J23),IF(M23="Compression",Q23-ABS(J23),Q23)) -> #VALUE! | S23: =IF(I22>=I23,ROUNDDOWN((newtonmethod(L23,R23)),6),ROUNDDOWN(M2oblique(L23,J23,1.4),6)) -> #VALUE! | T23: =IF(I22>=I23,p1p2(L23,S23,1.4),p1p2oblique(L23,J23,1.4)) -> #VALUE! | U23: =ROUNDDOWN((1/T23)*O23,6) -> #VALUE! | V23: =(1.4*O23*L23^2)/(2*(L23^2-1)) -> #VALUE! | W23: =(1.4*U23*S23^2)/(2*(S23^2-1)) -> #VALUE! | X23: =omega(L23,1.4) -> #VALUE! | Y23: =omega(S23,1.4) -> #VALUE! | Z23: =AD22 -> #VALUE! | AA23: =(dpds2(1.4,J23,L23,S23,O23,U23,V23,W23,E22,X23,Y23,G22,G23,Z23)) -> #VALUE! | AB23: =(eta(AA23,P23,U23,G23,D22,D23)) -> #VALUE! | AC23: =ROUNDDOWN(Pmainval(P23,U23,AB23),8) -> #VALUE! | AD23: =((dpds3(P23,U23,AC23,AA23))) -> #VALUE! | AE23: =U23/AC23 -> #VALUE! | AF23: =ROUNDDOWN((Machfinder(AE23,S23,1.4)),6) -> #VALUE! | AG23: =AC23/G$2 -> #VALUE! | AH23: =D23/D$3 -> 0.081818182 | AI23: =(2/(1.4*D$6^2))*(AG23-1) -> #VALUE! | AJ23: =IF(K23=FALSE(),drag(D22,D23,E22,E23,G23,P23,U23,AB23,AA23),0) -> #VALUE! | AN23: =ASIN(1/L23) -> #VALUE! | AO23: =ASIN(1/S23) -> #VALUE! | AP23: =2*1.4*O23/SIN(2*AN23) -> #VALUE! | AQ23: =2*1.4*U23/SIN(2*AO23) -> #VALUE! | AR23: =ROUNDDOWN(BILINTERP(inputtables!$A$48:$N$66,ABS(I23),D$6),8) -> #VALUE! | AS23: =AT22 -> #VALUE! | AT23: =DeltaL(M$16:M23,U23,O23,J23,M23,L23,1.4,AB23,G23,AR23,AP23,AQ23,AS23) -> #VALUE! | AU23: =IF(K23=TRUE(),Segment_Cnalpha(E22,E23,$J$2),cnalpha(D22,D23,E22,E23,G23,P23,U23,AB23,AA23,AP23,AQ23,AS23,AR23,J$3)) -> #VALUE! | AW23: =IF(K23=TRUE(),Segment_CMalpha(AU23,AX23),cmalpha1(D22,D23,E22,E23,G23,P23,U23,AB23,AA23,AP23,AQ23,AS23,AR23,J$3,D$4)) -> #VALUE! | AX23: =IF(K23=TRUE(),Segment_CP(D22,D23,E22,E23),-$D$4*AW23/AU23) -> #VALUE!
C24: =C23+1 -> 10 | D24: 5 | E24: 0.77036472 | F24: =(E24-E23) -> 0.046432101 | G24: =ROUNDDOWN(ATAN(F24/(D24-D23)),6) -> 0.092598 | H24: =IF(G24>0,F24/SIN(G24),D24-D23) -> 0.50215471 | I24: =ROUNDDOWN(G24*180/PI(),8) -> 5.3054746 | J24: =ROUNDDOWN(epsilonangle(G23,G24),8) -> #VALUE! | K24: =IF(K23=TRUE(),TRUE(),IF(M24="Compression",IF(G24>(0.3208*(L24^2-1)^(3/2)/L24^2),TRUE(),FALSE()),FALSE())) -> 0 | L24: =IF(ISERROR(AF23),L23,AF23) -> #VALUE! | M24: =IF(G24>G25,"Expansion",IF(G24=G25,"No Change","Compression")) -> Expansion | N24: =ROUNDDOWN(BILINTERP(inputtables!$A$26:$N$44,ABS(I24),D$6),8) -> #VALUE! | O24: =AC23 -> #VALUE! | P24: =N24*G$2 -> #VALUE! | Q24: =nu(L24,1.4) -> #VALUE! | R24: =IF(M24="Expansion",Q24+ABS(J24),IF(M24="Compression",Q24-ABS(J24),Q24)) -> #VALUE! | S24: =IF(I23>=I24,ROUNDDOWN((newtonmethod(L24,R24)),6),ROUNDDOWN(M2oblique(L24,J24,1.4),6)) -> #VALUE! | T24: =IF(I23>=I24,p1p2(L24,S24,1.4),p1p2oblique(L24,J24,1.4)) -> #VALUE! | U24: =ROUNDDOWN((1/T24)*O24,6) -> #VALUE! | V24: =(1.4*O24*L24^2)/(2*(L24^2-1)) -> #VALUE! | W24: =(1.4*U24*S24^2)/(2*(S24^2-1)) -> #VALUE! | X24: =omega(L24,1.4) -> #VALUE! | Y24: =omega(S24,1.4) -> #VALUE! | Z24: =AD23 -> #VALUE! | AA24: =(dpds2(1.4,J24,L24,S24,O24,U24,V24,W24,E23,X24,Y24,G23,G24,Z24)) -> #VALUE! | AB24: =(eta(AA24,P24,U24,G24,D23,D24)) -> #VALUE! | AC24: =ROUNDDOWN(Pmainval(P24,U24,AB24),8) -> #VALUE! | AD24: =((dpds3(P24,U24,AC24,AA24))) -> #VALUE! | AE24: =U24/AC24 -> #VALUE! | AF24: =ROUNDDOWN((Machfinder(AE24,S24,1.4)),6) -> #VALUE! | AG24: =AC24/G$2 -> #VALUE! | AH24: =D24/D$3 -> 0.090909091 | AI24: =(2/(1.4*D$6^2))*(AG24-1) -> #VALUE! | AJ24: =IF(K24=FALSE(),drag(D23,D24,E23,E24,G24,P24,U24,AB24,AA24),0) -> #VALUE! | AN24: =ASIN(1/L24) -> #VALUE! | AO24: =ASIN(1/S24) -> #VALUE! | AP24: =2*1.4*O24/SIN(2*AN24) -> #VALUE! | AQ24: =2*1.4*U24/SIN(2*AO24) -> #VALUE! | AR24: =ROUNDDOWN(BILINTERP(inputtables!$A$48:$N$66,ABS(I24),D$6),8) -> #VALUE! | AS24: =AT23 -> #VALUE! | AT24: =DeltaL(M$16:M24,U24,O24,J24,M24,L24,1.4,AB24,G24,AR24,AP24,AQ24,AS24) -> #VALUE! | AU24: =IF(K24=TRUE(),Segment_Cnalpha(E23,E24,$J$2),cnalpha(D23,D24,E23,E24,G24,P24,U24,AB24,AA24,AP24,AQ24,AS24,AR24,J$3)) -> #VALUE! | AW24: =IF(K24=TRUE(),Segment_CMalpha(AU24,AX24),cmalpha1(D23,D24,E23,E24,G24,P24,U24,AB24,AA24,AP24,AQ24,AS24,AR24,J$3,D$4)) -> #VALUE! | AX24: =IF(K24=TRUE(),Segment_CP(D23,D24,E23,E24),-$D$4*AW24/AU24) -> #VALUE!
C25: =C24+1 -> 11 | D25: 5.5 | E25: 0.81330367 | F25: =(E25-E24) -> 0.042938952 | G25: =ROUNDDOWN(ATAN(F25/(D25-D24)),6) -> 0.085667 | H25: =IF(G25>0,F25/SIN(G25),D25-D24) -> 0.50184455 | I25: =ROUNDDOWN(G25*180/PI(),8) -> 4.9083575 | J25: =ROUNDDOWN(epsilonangle(G24,G25),8) -> #VALUE! | K25: =IF(K24=TRUE(),TRUE(),IF(M25="Compression",IF(G25>(0.3208*(L25^2-1)^(3/2)/L25^2),TRUE(),FALSE()),FALSE())) -> 0 | L25: =IF(ISERROR(AF24),L24,AF24) -> #VALUE! | M25: =IF(G25>G26,"Expansion",IF(G25=G26,"No Change","Compression")) -> Expansion | N25: =ROUNDDOWN(BILINTERP(inputtables!$A$26:$N$44,ABS(I25),D$6),8) -> #VALUE! | O25: =AC24 -> #VALUE! | P25: =N25*G$2 -> #VALUE! | Q25: =nu(L25,1.4) -> #VALUE! | R25: =IF(M25="Expansion",Q25+ABS(J25),IF(M25="Compression",Q25-ABS(J25),Q25)) -> #VALUE! | S25: =IF(I24>=I25,ROUNDDOWN((newtonmethod(L25,R25)),6),ROUNDDOWN(M2oblique(L25,J25,1.4),6)) -> #VALUE! | T25: =IF(I24>=I25,p1p2(L25,S25,1.4),p1p2oblique(L25,J25,1.4)) -> #VALUE! | U25: =ROUNDDOWN((1/T25)*O25,6) -> #VALUE! | V25: =(1.4*O25*L25^2)/(2*(L25^2-1)) -> #VALUE! | W25: =(1.4*U25*S25^2)/(2*(S25^2-1)) -> #VALUE! | X25: =omega(L25,1.4) -> #VALUE! | Y25: =omega(S25,1.4) -> #VALUE! | Z25: =AD24 -> #VALUE! | AA25: =(dpds2(1.4,J25,L25,S25,O25,U25,V25,W25,E24,X25,Y25,G24,G25,Z25)) -> #VALUE! | AB25: =(eta(AA25,P25,U25,G25,D24,D25)) -> #VALUE! | AC25: =ROUNDDOWN(Pmainval(P25,U25,AB25),8) -> #VALUE! | AD25: =((dpds3(P25,U25,AC25,AA25))) -> #VALUE! | AE25: =U25/AC25 -> #VALUE! | AF25: =ROUNDDOWN((Machfinder(AE25,S25,1.4)),6) -> #VALUE! | AG25: =AC25/G$2 -> #VALUE! | AH25: =D25/D$3 -> 0.1 | AI25: =(2/(1.4*D$6^2))*(AG25-1) -> #VALUE! | AJ25: =IF(K25=FALSE(),drag(D24,D25,E24,E25,G25,P25,U25,AB25,AA25),0) -> #VALUE! | AN25: =ASIN(1/L25) -> #VALUE! | AO25: =ASIN(1/S25) -> #VALUE! | AP25: =2*1.4*O25/SIN(2*AN25) -> #VALUE! | AQ25: =2*1.4*U25/SIN(2*AO25) -> #VALUE! | AR25: =ROUNDDOWN(BILINTERP(inputtables!$A$48:$N$66,ABS(I25),D$6),8) -> #VALUE! | AS25: =AT24 -> #VALUE! | AT25: =DeltaL(M$16:M25,U25,O25,J25,M25,L25,1.4,AB25,G25,AR25,AP25,AQ25,AS25) -> #VALUE! | AU25: =IF(K25=TRUE(),Segment_Cnalpha(E24,E25,$J$2),cnalpha(D24,D25,E24,E25,G25,P25,U25,AB25,AA25,AP25,AQ25,AS25,AR25,J$3)) -> #VALUE! | AW25: =IF(K25=TRUE(),Segment_CMalpha(AU25,AX25),cmalpha1(D24,D25,E24,E25,G25,P25,U25,AB25,AA25,AP25,AQ25,AS25,AR25,J$3,D$4)) -> #VALUE! | AX25: =IF(K25=TRUE(),Segment_CP(D24,D25,E24,E25),-$D$4*AW25/AU25) -> #VALUE!
C26: =C25+1 -> 12 | D26: 6 | E26: 0.85296219 | F26: =(E26-E25) -> 0.039658518 | G26: =ROUNDDOWN(ATAN(F26/(D26-D25)),6) -> 0.079151 | H26: =IF(G26>0,F26/SIN(G26),D26-D25) -> 0.50157241 | I26: =ROUNDDOWN(G26*180/PI(),8) -> 4.5350182 | J26: =ROUNDDOWN(epsilonangle(G25,G26),8) -> #VALUE! | K26: =IF(K25=TRUE(),TRUE(),IF(M26="Compression",IF(G26>(0.3208*(L26^2-1)^(3/2)/L26^2),TRUE(),FALSE()),FALSE())) -> 0 | L26: =IF(ISERROR(AF25),L25,AF25) -> #VALUE! | M26: =IF(G26>G27,"Expansion",IF(G26=G27,"No Change","Compression")) -> Expansion | N26: =ROUNDDOWN(BILINTERP(inputtables!$A$26:$N$44,ABS(I26),D$6),8) -> #VALUE! | O26: =AC25 -> #VALUE! | P26: =N26*G$2 -> #VALUE! | Q26: =nu(L26,1.4) -> #VALUE! | R26: =IF(M26="Expansion",Q26+ABS(J26),IF(M26="Compression",Q26-ABS(J26),Q26)) -> #VALUE! | S26: =IF(I25>=I26,ROUNDDOWN((newtonmethod(L26,R26)),6),ROUNDDOWN(M2oblique(L26,J26,1.4),6)) -> #VALUE! | T26: =IF(I25>=I26,p1p2(L26,S26,1.4),p1p2oblique(L26,J26,1.4)) -> #VALUE! | U26: =ROUNDDOWN((1/T26)*O26,6) -> #VALUE! | V26: =(1.4*O26*L26^2)/(2*(L26^2-1)) -> #VALUE! | W26: =(1.4*U26*S26^2)/(2*(S26^2-1)) -> #VALUE! | X26: =omega(L26,1.4) -> #VALUE! | Y26: =omega(S26,1.4) -> #VALUE! | Z26: =AD25 -> #VALUE! | AA26: =(dpds2(1.4,J26,L26,S26,O26,U26,V26,W26,E25,X26,Y26,G25,G26,Z26)) -> #VALUE! | AB26: =(eta(AA26,P26,U26,G26,D25,D26)) -> #VALUE! | AC26: =ROUNDDOWN(Pmainval(P26,U26,AB26),8) -> #VALUE! | AD26: =((dpds3(P26,U26,AC26,AA26))) -> #VALUE! | AE26: =U26/AC26 -> #VALUE! | AF26: =ROUNDDOWN((Machfinder(AE26,S26,1.4)),6) -> #VALUE! | AG26: =AC26/G$2 -> #VALUE! | AH26: =D26/D$3 -> 0.10909091 | AI26: =(2/(1.4*D$6^2))*(AG26-1) -> #VALUE! | AJ26: =IF(K26=FALSE(),drag(D25,D26,E25,E26,G26,P26,U26,AB26,AA26),0) -> #VALUE! | AN26: =ASIN(1/L26) -> #VALUE! | AO26: =ASIN(1/S26) -> #VALUE! | AP26: =2*1.4*O26/SIN(2*AN26) -> #VALUE! | AQ26: =2*1.4*U26/SIN(2*AO26) -> #VALUE! | AR26: =ROUNDDOWN(BILINTERP(inputtables!$A$48:$N$66,ABS(I26),D$6),8) -> #VALUE! | AS26: =AT25 -> #VALUE! | AT26: =DeltaL(M$16:M26,U26,O26,J26,M26,L26,1.4,AB26,G26,AR26,AP26,AQ26,AS26) -> #VALUE! | AU26: =IF(K26=TRUE(),Segment_Cnalpha(E25,E26,$J$2),cnalpha(D25,D26,E25,E26,G26,P26,U26,AB26,AA26,AP26,AQ26,AS26,AR26,J$3)) -> #VALUE! | AW26: =IF(K26=TRUE(),Segment_CMalpha(AU26,AX26),cmalpha1(D25,D26,E25,E26,G26,P26,U26,AB26,AA26,AP26,AQ26,AS26,AR26,J$3,D$4)) -> #VALUE! | AX26: =IF(K26=TRUE(),Segment_CP(D25,D26,E25,E26),-$D$4*AW26/AU26) -> #VALUE!
C27: =C26+1 -> 13 | D27: 6.5 | E27: 0.88951297 | F27: =(E27-E26) -> 0.036550779 | G27: =ROUNDDOWN(ATAN(F27/(D27-D26)),6) -> 0.072971 | H27: =IF(G27>0,F27/SIN(G27),D27-D26) -> 0.50133939 | I27: =ROUNDDOWN(G27*180/PI(),8) -> 4.1809303 | J27: =ROUNDDOWN(epsilonangle(G26,G27),8) -> #VALUE! | K27: =IF(K26=TRUE(),TRUE(),IF(M27="Compression",IF(G27>(0.3208*(L27^2-1)^(3/2)/L27^2),TRUE(),FALSE()),FALSE())) -> 0 | L27: =IF(ISERROR(AF26),L26,AF26) -> #VALUE! | M27: =IF(G27>G28,"Expansion",IF(G27=G28,"No Change","Compression")) -> Expansion | N27: =ROUNDDOWN(BILINTERP(inputtables!$A$26:$N$44,ABS(I27),D$6),8) -> #VALUE! | O27: =AC26 -> #VALUE! | P27: =N27*G$2 -> #VALUE! | Q27: =nu(L27,1.4) -> #VALUE! | R27: =IF(M27="Expansion",Q27+ABS(J27),IF(M27="Compression",Q27-ABS(J27),Q27)) -> #VALUE! | S27: =IF(I26>=I27,ROUNDDOWN((newtonmethod(L27,R27)),6),ROUNDDOWN(M2oblique(L27,J27,1.4),6)) -> #VALUE! | T27: =IF(I26>=I27,p1p2(L27,S27,1.4),p1p2oblique(L27,J27,1.4)) -> #VALUE! | U27: =ROUNDDOWN((1/T27)*O27,6) -> #VALUE! | V27: =(1.4*O27*L27^2)/(2*(L27^2-1)) -> #VALUE! | W27: =(1.4*U27*S27^2)/(2*(S27^2-1)) -> #VALUE! | X27: =omega(L27,1.4) -> #VALUE! | Y27: =omega(S27,1.4) -> #VALUE! | Z27: =AD26 -> #VALUE! | AA27: =(dpds2(1.4,J27,L27,S27,O27,U27,V27,W27,E26,X27,Y27,G26,G27,Z27)) -> #VALUE! | AB27: =(eta(AA27,P27,U27,G27,D26,D27)) -> #VALUE! | AC27: =ROUNDDOWN(Pmainval(P27,U27,AB27),8) -> #VALUE! | AD27: =((dpds3(P27,U27,AC27,AA27))) -> #VALUE! | AE27: =U27/AC27 -> #VALUE! | AF27: =ROUNDDOWN((Machfinder(AE27,S27,1.4)),6) -> #VALUE! | AG27: =AC27/G$2 -> #VALUE! | AH27: =D27/D$3 -> 0.11818182 | AI27: =(2/(1.4*D$6^2))*(AG27-1) -> #VALUE! | AJ27: =IF(K27=FALSE(),drag(D26,D27,E26,E27,G27,P27,U27,AB27,AA27),0) -> #VALUE! | AN27: =ASIN(1/L27) -> #VALUE! | AO27: =ASIN(1/S27) -> #VALUE! | AP27: =2*1.4*O27/SIN(2*AN27) -> #VALUE! | AQ27: =2*1.4*U27/SIN(2*AO27) -> #VALUE! | AR27: =ROUNDDOWN(BILINTERP(inputtables!$A$48:$N$66,ABS(I27),D$6),8) -> #VALUE! | AS27: =AT26 -> #VALUE! | AT27: =DeltaL(M$16:M27,U27,O27,J27,M27,L27,1.4,AB27,G27,AR27,AP27,AQ27,AS27) -> #VALUE! | AU27: =IF(K27=TRUE(),Segment_Cnalpha(E26,E27,$J$2),cnalpha(D26,D27,E26,E27,G27,P27,U27,AB27,AA27,AP27,AQ27,AS27,AR27,J$3)) -> #VALUE! | AW27: =IF(K27=TRUE(),Segment_CMalpha(AU27,AX27),cmalpha1(D26,D27,E26,E27,G27,P27,U27,AB27,AA27,AP27,AQ27,AS27,AR27,J$3,D$4)) -> #VALUE! | AX27: =IF(K27=TRUE(),Segment_CP(D26,D27,E26,E27),-$D$4*AW27/AU27) -> #VALUE!
... C49: =C48+1 -> 35 | D49: 55 | E49: 1.125 | F49: =(E49-E48) -> 0 | G49: =ROUNDDOWN(ATAN(F49/(D49-D48)),6) -> 0 | H49: =IF(G49>0,F49/SIN(G49),D49-D48) -> 5 | I49: =ROUNDDOWN(G49*180/PI(),8) -> 0 | J49: =ROUNDDOWN(epsilonangle(G48,G49),8) -> #VALUE! | K49: =IF(K48=TRUE(),TRUE(),IF(M49="Compression",IF(G49>(0.3208*(L49^2-1)^(3/2)/L49^2),TRUE(),FALSE()),FALSE())) -> 0 | L49: =IF(ISERROR(AF48),L48,AF48) -> #VALUE! | M49: =IF(G49>G50,"Expansion",IF(G49=G50,"No Change","Compression")) -> No Change | N49: =ROUNDDOWN(BILINTERP(inputtables!$A$26:$N$44,ABS(I49),D$6),8) -> #VALUE! | O49: =AC48 -> #VALUE! | P49: =N49*G$2 -> #VALUE! | Q49: =nu(L49,1.4) -> #VALUE! | R49: =IF(M49="Expansion",Q49+ABS(J49),IF(M49="Compression",Q49-ABS(J49),Q49)) -> #VALUE! | S49: =IF(I48>=I49,ROUNDDOWN((newtonmethod(L49,R49)),6),ROUNDDOWN(M2oblique(L49,J49,1.4),6)) -> #VALUE! | T49: =IF(I48>=I49,p1p2(L49,S49,1.4),p1p2oblique(L49,J49,1.4)) -> #VALUE! | U49: =ROUNDDOWN((1/T49)*O49,6) -> #VALUE! | V49: =(1.4*O49*L49^2)/(2*(L49^2-1)) -> #VALUE! | W49: =(1.4*U49*S49^2)/(2*(S49^2-1)) -> #VALUE! | X49: =omega(L49,1.4) -> #VALUE! | Y49: =omega(S49,1.4) -> #VALUE! | Z49: =AD48 -> #VALUE! | AA49: =(dpds2(1.4,J49,L49,S49,O49,U49,V49,W49,E48,X49,Y49,G48,G49,Z49)) -> #VALUE! | AB49: =(eta(AA49,P49,U49,G49,D48,D49)) -> #VALUE! | AC49: =ROUNDDOWN(Pmainval(P49,U49,AB49),8) -> #VALUE! | AD49: =((dpds3(P49,U49,AC49,AA49))) -> #VALUE! | AE49: =U49/AC49 -> #VALUE! | AF49: =ROUNDDOWN((Machfinder(AE49,S49,1.4)),6) -> #VALUE! | AG49: =AC49/G$2 -> #VALUE! | AH49: =D49/D$3 -> 1 | AI49: =(2/(1.4*D$6^2))*(AG49-1) -> #VALUE! | AJ49: =IF(K49=FALSE(),drag(D48,D49,E48,E49,G49,P49,U49,AB49,AA49),0) -> #VALUE! | AN49: =ASIN(1/L49) -> #VALUE! | AO49: =ASIN(1/S49) -> #VALUE! | AP49: =2*1.4*O49/SIN(2*AN49) -> #VALUE! | AQ49: =2*1.4*U49/SIN(2*AO49) -> #VALUE! | AR49: =ROUNDDOWN(BILINTERP(inputtables!$A$48:$N$66,ABS(I49),D$6),8) -> #VALUE! | AS49: =AT48 -> #VALUE! | AT49: =DeltaL(M$16:M49,U49,O49,J49,M49,L49,1.4,AB49,G49,AR49,AP49,AQ49,AS49) -> #VALUE! | AU49: =IF(K49=TRUE(),Segment_Cnalpha(E48,E49,$J$2),cnalpha(D48,D49,E48,E49,G49,P49,U49,AB49,AA49,AP49,AQ49,AS49,AR49,J$3)) -> #VALUE! | AW49: =IF(K49=TRUE(),Segment_CMalpha(AU49,AX49),cmalpha1(D48,D49,E48,E49,G49,P49,U49,AB49,AA49,AP49,AQ49,AS49,AR49,J$3,D$4)) -> #VALUE! | AX49: =IF(K49=TRUE(),Segment_CP(D48,D49,E48,E49),-$D$4*AW49/AU49) -> #VALUE!
C50: =C49+1 -> 36
C51: =C50+1 -> 37
C52: =C51+1 -> 38
C53: =C52+1 -> 39
C54: =C53+1 -> 40
C55: =C54+1 -> 41
C56: =C55+1 -> 42
C57: =C56+1 -> 43
C58: =C57+1 -> 44
C59: =C58+1 -> 45
C60: =C59+1 -> 46
AN61: For 2 Stages
A63: First Stage → | B63: Number of Fin Sets or Stages | C63: Number of Fin Panels | D63: Fin Root Chord Leading Edge Distance from Nose Tip, in | E63: Body Radius at Fin Center of Pressure Station, in | F63: Root Chord, cR, in | G63: Tip Chord, cT, in | H63: Fin Exposed Semi span, b, in | I63: Wedge delta (half angle), deg | J63: Wedge delta, rad | K63: Maximum Semispan from Body CL, in | L63: Taper Ratio, λ | M63: Cot (leading edge sweep), cotΛ | O63: β = √ M2 - 1 | P63: 2-Panel Fin Area, S, in2 | Q63: 2-Panel Aspect Ratio, AR | S63: Wedge Multiplier | T63: λcR/βs | U63: βcotΛ | V63: (∂CN/∂α)/ AR, rad-1 | W63: Wing Alone CNa (based on Swing), rad-1 | X63: h/c, Fin Center of Pressure, Fraction of Root Chord, aft of Fin Apex | Y63: Body-Fin Lift Interference, KW(B), Eq. (14) | Z63: Naked (single panel) Fin Ass'y CNa (based on Sref), rad-1 | AA63: Fin-Body Lift Interference, KB(W), Eq. (21) | AB63: Fins + K(W)B CNα, rad-1 | AC63: Fin + K(W)B Center of Pressure, in | AD63: Fins + KW(B) Moment About the Nose Tip | AE63: Tail Assembly CNa, rad-1 | AG63: B(W) Center of Pressure Station, in | AH63: Body B(W) Lift Moment About Nose Tip | AI63: Body-Fin Lift Interference, KW(B), Eq. (21) | AJ63: Tail Assembly α and d Center of Pressure, in | AK63: Single Panel CNδ, rad-1 | AL63: Fin Wave Drag for Wedge, CDw | AN63: Trailing Vortex Spanwise Location at Stage 1, in | AO63: Image Vortex Spanwise Location at Stage 1, in | AP63: Vortex Iinterference Multiplier | AQ63: cR1b1-cT1R1, in2 | AR63: cR1-cT1, in | AS63: N(f1) | AT63: ΔN(f1) | AU63: NI(g1) | AV63: ΔNI(g1)) | AW63: First Stage Fins Vortex Interference CNa | AX63: First Stage Body Vortex Interference CNa, rad-1 | AY63: Total Tail Assembly CNα with Vortex Interference , rad-1 | AZ63: Body-Fin Lift Interference, kW(B), Eq. (19) | BA63: Fin-Body Lift Interference, kB(W), Eq. (33) | BB63: Single Panel CNd, rad-1
B64: 1 | C64: 4 | D64: 50 | E64: 1.125 | F64: 4 | G64: 2 | H64: 1.5 | I64: 0 | J64: =I64*PI()/180 -> 0 | K64: =H64+E64 -> 2.625 | L64: =G64/F64 -> 0.5 | M64: =H64/(F64-G64) -> 0.75 | O64: =SQRT(D6^2-1) -> 1.2489996 | P64: =(F64+G64)*H64 -> 9 | Q64: =4*H64^2/P64 -> 1 | S64: =Wedge_multiplier(D6,J64,F64,G64,H64) -> #VALUE! | T64: =G64/(O64*H64) -> 1.067521 | U64: =O64*M64 -> 0.9367497 | V64: =BILINTERP(inputtables!$A$69:$G$82,SupersonicCalculations!T64,SupersonicCalculations!U64) -> #VALUE! | W64: =Cnalpha_WingAlone(C10,D10,E10,F64,G64,H64,Q64,S64,V64) -> #VALUE! | X64: =HC_FinCP_aft(C10,D10,E10,F64,G64,H64,inputtables!$A$85:$G$98,T64,U64,W64) -> #VALUE! | Y64: =2*((1+(E64/K64)^4)*(ATAN((K64/E64-E64/K64)/2)/2+PI()/4)-((E64/K64)^2)*((K64/E64-E64/K64)+2*ATAN(E64/K64)))/(PI()*(1-E64/K64)^2) -> 1.3777138 | Z64: =C64*W64*P64/(2*J2) -> #VALUE! | AA64: =(((1-(E64/K64)^2)^2)-(2/PI())*((1+(E64/K64)^4)*(ATAN((K64/E64-E64/K64)/2)/2+PI()/4)-((E64/K64)^2)*(K64/E64-E64/K64+2*ATAN(E64/K64))))/(1-E64/K64)^2 -> 0.66310251 | AB64: =Y64*Z64 -> #VALUE! | AC64: =D64+X64*F64 -> #VALUE! | AD64: =AB64*AC64 -> #VALUE! | AE64: =AB64+AA64*Z64 -> #VALUE! | AG64: =IF((K64>2*E64),D64+F64/24+(K64-E64)*((F64-G64)/(2*H64))*((E64/(E64-K64))+(SQRT(K64*(K64-2*E64))*ACOSH((K64-E64)/E64)-K64+E64+PI()*E64/2)/(((K64-E64)*E64/SQRT(K64*(K64-2*E64)))*ACOSH((K64-E64)/E64)+(K64-E64)^2/E64-PI()*(K64-E64)/2)),AC64) -> 50.476549 | AH64: =Z64*AA64*AG64 -> #VALUE! | AI64: =(PI()^2*(K64/E64+1)^2/(4*(K64/E64)^2)+PI()*((K64/E64)^2+1)^2/((K64/E64)^2*(K64/E64-1)^2)*ASIN(((K64/E64)^2-1)/((K64/E64)^2+1))-2*PI()*(K64/E64+1)/((K64/E64)*(K64/E64-1))+((K64/E64)^2+1)^2/((K64/E64)^2*(K64/E64-1)^2)*(ASIN(((K64/E64)^2-1)/((K64/E64)^2+1)))^2-(4*(K64/E64+1)/((K64/E64)*(K64/E64-1)))*ASIN(((K64/E64)^2-1)/((K64/E64)^2+1))+(8/(K64/E64-1)^2)*LN(((K64/E64)^2+1)/(2*K64/E64)))/PI()^2 -> 0.93600105 | AJ64: =(AD64+AH64)/AE64 -> #VALUE! | AK64: =W64*AI64*P64/(2*J2) -> #VALUE! | AL64: =Wedge_wavedrageCoef(D6,J64,F64,G64,H64) -> #VALUE! | AN64: =SQRT(AN67^2+E64^2-E67^2) -> 1.4761424 | AO64: =E64^2/AN64 -> 0.85738677 | AP64: =W67*Y67*C67/(16*PI()*(AN67-E67)*H64) -> #VALUE! | AQ64: =F64*K64-G64*E64 -> 8.25 | AR64: =F64-G64 -> 2 | AS64: =AQ64*LN((K64-AN64)/(AN64-E64))-AR64*(H64+AN64*LN((K64-AN64)/(AN64-E64))) -> 3.2795477 | AT64: =-(AQ64+AN64*AR64)*LN((K64+AN64)/(AN64+E64))-AR64*H64 -> -8.1005664 | AU64: =-(AQ64-AR64*AO64)*LN((K64-AO64)/(E64-AO64))-AR64*H64 -> -15.337479 | AV64: =(AQ64+AR64*AO64)*LN((K64+AO64)/(E64+AO64))-AR64*H64 -> 2.6143164 | AW64: =AP64*(AS64+AT64+AU64+AV64) -> #VALUE! | AX64: =-4*AO67*((AN67^2-E67^2)/AN67-AN64+E64^2/AN64)/J2 -> #VALUE! | AY64: =AE64+AW64+AX64 -> #VALUE! | AZ64: =(PI()^2*(K64/E64+1)^2/(4*(K64/E64)^2)+PI()*((K64/E64)^2+1)^2/((K64/E64)^2*(K64/E64-1)^2)*ASIN(((K64/E64)^2-1)/((K64/E64)^2+1))-2*PI()*(K64/E64+1)/((K64/E64)*(K64/E64-1))+((K64/E64)^2+1)^2/((K64/E64)^2*(K64/E64-1)^2)*(ASIN(((K64/E64)^2-1)/((K64/E64)^2+1)))^2-(4*(K64/E64+1)/((K64/E64)*(K64/E64-1)))*ASIN(((K64/E64)^2-1)/((K64/E64)^2+1))+(8/(K64/E64-1)^2)*LN(((K64/E64)^2+1)/(2*K64/E64)))/PI()^2 -> 0.93600105 | BA64: =Y64-AZ64 -> 0.44171277 | BB64: =(AZ64+BA64)*AK64 -> #VALUE!
...

Sheet Sheet1
A1: M
A2: 1.1 | B2: =(PI()*(A2^2-1)^1.5/(3.24*A2^3*(1-EXP(-5.5*(A2-1)))))*180/PI() -> 9.4948146
A3: 1.2 | B3: =(PI()*(A3^2-1)^1.5/(3.24*A3^3*(1-EXP(-5.5*(A3-1)))))*180/PI() -> 14.06543
A4: 1.3 | B4: =(PI()*(A4^2-1)^1.5/(3.24*A4^3*(1-EXP(-5.5*(A4-1)))))*180/PI() -> 17.938517
A5: 1.4 | B5: =(PI()*(A5^2-1)^1.5/(3.24*A5^3*(1-EXP(-5.5*(A5-1)))))*180/PI() -> 21.416689
A6: 1.5 | B6: =(PI()*(A6^2-1)^1.5/(3.24*A6^3*(1-EXP(-5.5*(A6-1)))))*180/PI() -> 24.575899
A7: 1.6 | B7: =(PI()*(A7^2-1)^1.5/(3.24*A7^3*(1-EXP(-5.5*(A7-1)))))*180/PI() -> 27.439454
A8: 1.7 | B8: =(PI()*(A8^2-1)^1.5/(3.24*A8^3*(1-EXP(-5.5*(A8-1)))))*180/PI() -> 30.020288
A9: 1.8 | B9: =(PI()*(A9^2-1)^1.5/(3.24*A9^3*(1-EXP(-5.5*(A9-1)))))*180/PI() -> 32.333074
A10: 1.9 | B10: =(PI()*(A10^2-1)^1.5/(3.24*A10^3*(1-EXP(-5.5*(A10-1)))))*180/PI() -> 34.396534
A11: 2 | B11: =(PI()*(A11^2-1)^1.5/(3.24*A11^3*(1-EXP(-5.5*(A11-1)))))*180/PI() -> 36.232466
A12: 2.5 | B12: =(PI()*(A12^2-1)^1.5/(3.24*A12^3*(1-EXP(-5.5*(A12-1)))))*180/PI() -> 42.781884
A13: 3 | B13: =(PI()*(A13^2-1)^1.5/(3.24*A13^3*(1-EXP(-5.5*(A13-1)))))*180/PI() -> 46.559249
... A17: 5 | B17: =(PI()*(A17^2-1)^1.5/(3.24*A17^3*(1-EXP(-5.5*(A17-1)))))*180/PI() -> 52.255781
P22: CaseB | S22: CaseC
A23: Root Chord, cR, in | B23: Tip Chord, cT, in | C23: Fin Exposed Semi span, b, in | D23: Wedge delta (half angle), deg | E23: Wedge delta, rad | F23: Leading Edge Sweep, Λ, rad | H23: Minimum Mach no. (Tip Interference) 1st Stage | I23: Maximum Mach no. (Subsonic Leading Edge) 1st Stage | J23: Minimum Mach no. (Sonic Leading Edge) 1st Stage | N23: Root Chord, cR, in | O23: Tip Chord, cT, in | P23: Fin Exposed Semi span, b, in | Q23: Leading Edge Sweep, Λ, rad | S23: Root Chord, cR, in | T23: Tip Chord, cT, in | U23: Fin Exposed Semi span, b, in | V23: Leading Edge Sweep, Λ, rad | Y23: Root Chord, cR, in | Z23: Tip Chord, cT, in | AA23: Fin Exposed Semi span, b, in | AB23: Leading Edge Sweep, Λ, rad | AD23: Minimum Mach no. (Tip Interference) 1st Stage | AE23: Maximum Mach no. (Subsonic Leading Edge) 1st Stage | AF23: Minimum Mach no. (Sonic Leading Edge) 1st Stage
A24: 4 | B24: 2 | C24: 1.5 | D24: 5 | E24: =D24*PI()/180 -> 0.087266463 | F24: =LEsweepangle(A24,B24,C24) -> #VALUE! | H24: =SQRT(1+B24/(2*C24)) -> 1.2909944 | I24: =SQRT(1+1/((1/TAN(F24))^2)) -> #VALUE! | J24: =SQRT((A24/B24)^2+1) -> 2.236068 | N24: 4 | O24: 3 | P24: 1.5 | Q24: =LEsweepangle(N24,O24,P24) -> #VALUE! | S24: 4 | T24: 3 | U24: 1.5 | V24: =LEsweepangle(S24,T24,U24) -> #VALUE! | Y24: 4 | Z24: 2 | AA24: 1.5 | AB24: =LEsweepangle(Y24,Z24,AA24) -> #VALUE! | AD24: =SQRT(1+Z24/(2*AA24)) -> 1.2909944 | AE24: =SQRT(1+1/((1/TAN(AB24))^2)) -> #VALUE! | AF24: =SQRT((Y24/Z24)^2+1) -> 2.236068
Y25: 4 | Z25: 4 | AA25: 1.5 | AB25: =LEsweepangle(Y25,Z25,AA25) -> #VALUE! | AD25: =SQRT(1+Z25/(2*AA25)) -> 1.5275252 | AE25: =SQRT(1+1/((1/TAN(AB25))^2)) -> #VALUE! | AF25: =SQRT((Y25/Z25)^2+1) -> 1.4142136
E26: Wmultiplier for M w/o LE correction | H26: M w/ LE correction | Y26: 4 | Z26: 2.6 | AA26: 1.5 | AB26: =LEsweepangle(Y26,Z26,AA26) -> #VALUE! | AD26: =SQRT(1+Z26/(2*AA26)) -> 1.3662601 | AE26: =SQRT(1+1/((1/TAN(AB26))^2)) -> #VALUE! | AF26: =SQRT((Y26/Z26)^2+1) -> 1.8349016
A27: Minf | B27: M at LE | C27: Maximum Wedge Half Angle for Supersonic Wedge Surface Flow, rad | E27: Wedge Multiplier | F27: Fin Wave Drag for Wedge, CDw | H27: Wedge Multiplier | I27: Fin Wave Drag for Wedge, CDw | K27: M | L27: Minf | M27: Wedge Multipler (5 degree no M limit) | O27: M at LE | P27: Wedge Multiplier | Q27: Fin Wave Drag for Wedge, CDw | S27: M at LE | T27: Wedge Multiplier | U27: Fin Wave Drag for Wedge, CDw | Y27: 4 | Z27: 2 | AA27: 3 | AB27: =LEsweepangle(Y27,Z27,AA27) -> #VALUE! | AD27: =SQRT(1+Z27/(2*AA27)) -> 1.1547005 | AE27: =SQRT(1+1/((1/TAN(AB27))^2)) -> #VALUE! | AF27: =SQRT((Y27/Z27)^2+1) -> 2.236068
A28: 1.02 | B28: =A28*COS($F$24) -> #VALUE! | C28: =Wedge_HalfAngle(A28,$A$24,$B$24,$C$24) -> #VALUE! | E28: =Wedge_multiplier(A28/COS($F$24),$E$24,$A$24,$B$24,$C$24) -> #VALUE! | F28: =Wedge_wavedrageCoef(A28/COS($F$24),$E$24,$A$24,$B$24,$C$24) -> #VALUE! | H28: =Wedge_multiplier(A28,$E$24,$A$24,$B$24,$C$24) -> #VALUE! | I28: =Wedge_wavedrageCoef(A28,$E$24,$A$24,$B$24,$C$24) -> #VALUE! | K28: 1.1 | L28: =K28/COS($F$24) -> #VALUE! | M28: 5.0619645 | O28: =A28*COS($Q$24) -> #VALUE! | P28: =Wedge_multiplier(A28,$E$24,$N$24,$O$24,$P$24) -> #VALUE! | Q28: =Wedge_wavedrageCoef(A28,$E$24,$N$24,$O$24,$P$24) -> #VALUE! | S28: =A28*COS($V$24) -> #VALUE! | T28: =Wedge_multiplier(A28,$E$24,$S$24,$T$24,$U$24) -> #VALUE! | U28: =Wedge_wavedrageCoef(A28,$E$24,$S$24,$T$24,$U$24) -> #VALUE! | Y28: 4 | Z28: 2 | AA28: 4 | AB28: =LEsweepangle(Y28,Z28,AA28) -> #VALUE! | AD28: =SQRT(1+Z28/(2*AA28)) -> 1.118034 | AE28: =SQRT(1+1/((1/TAN(AB28))^2)) -> #VALUE! | AF28: =SQRT((Y28/Z28)^2+1) -> 2.236068
A29: 1.05 | B29: =A29*COS($F$24) -> #VALUE! | C29: =Wedge_HalfAngle(A29,$A$24,$B$24,$C$24) -> #VALUE! | E29: =Wedge_multiplier(A29/COS($F$24),$E$24,$A$24,$B$24,$C$24) -> #VALUE! | F29: =Wedge_wavedrageCoef(A29/COS($F$24),$E$24,$A$24,$B$24,$C$24) -> #VALUE! | H29: =Wedge_multiplier(A29,$E$24,$A$24,$B$24,$C$24) -> #VALUE! | I29: =Wedge_wavedrageCoef(A29,$E$24,$A$24,$B$24,$C$24) -> #VALUE! | K29: 1.2 | L29: =K29/COS($F$24) -> #VALUE! | M29: 1.8841437 | O29: =A29*COS($Q$24) -> #VALUE! | P29: =Wedge_multiplier(A29,$E$24,$N$24,$O$24,$P$24) -> #VALUE! | Q29: =Wedge_wavedrageCoef(A29,$E$24,$N$24,$O$24,$P$24) -> #VALUE! | S29: =A29*COS($V$24) -> #VALUE! | T29: =Wedge_multiplier(A29,$E$24,$S$24,$T$24,$U$24) -> #VALUE! | U29: =Wedge_wavedrageCoef(A29,$E$24,$S$24,$T$24,$U$24) -> #VALUE! | Y29: 4 | Z29: 4 | AA29: 2 | AB29: =LEsweepangle(Y29,Z29,AA29) -> #VALUE! | AD29: =SQRT(1+Z29/(2*AA29)) -> 1.4142136 | AE29: =SQRT(1+1/((1/TAN(AB29))^2)) -> #VALUE! | AF29: =SQRT((Y29/Z29)^2+1) -> 1.4142136
A30: 1.1 | B30: =A30*COS($F$24) -> #VALUE! | C30: =Wedge_HalfAngle(A30,$A$24,$B$24,$C$24) -> #VALUE! | E30: =Wedge_multiplier(A30/COS($F$24),$E$24,$A$24,$B$24,$C$24) -> #VALUE! | F30: =Wedge_wavedrageCoef(A30/COS($F$24),$E$24,$A$24,$B$24,$C$24) -> #VALUE! | H30: =Wedge_multiplier(A30,$E$24,$A$24,$B$24,$C$24) -> #VALUE! | I30: =Wedge_wavedrageCoef(A30,$E$24,$A$24,$B$24,$C$24) -> #VALUE! | K30: 1.3 | L30: =K30/COS($F$24) -> #VALUE! | M30: 1.4495515 | O30: =A30*COS($Q$24) -> #VALUE! | P30: =Wedge_multiplier(A30,$E$24,$N$24,$O$24,$P$24) -> #VALUE! | Q30: =Wedge_wavedrageCoef(A30,$E$24,$N$24,$O$24,$P$24) -> #VALUE! | S30: =A30*COS($V$24) -> #VALUE! | T30: =Wedge_multiplier(A30,$E$24,$S$24,$T$24,$U$24) -> #VALUE! | U30: =Wedge_wavedrageCoef(A30,$E$24,$S$24,$T$24,$U$24) -> #VALUE! | Y30: 4 | Z30: 5 | AA30: 1 | AB30: =LEsweepangle(Y30,Z30,AA30) -> #VALUE! | AD30: =SQRT(1+Z30/(2*AA30)) -> 1.8708287 | AE30: =SQRT(1+1/((1/TAN(AB30))^2)) -> #VALUE! | AF30: =SQRT((Y30/Z30)^2+1) -> 1.2806248
A31: 1.2 | B31: =A31*COS($F$24) -> #VALUE! | C31: =Wedge_HalfAngle(A31,$A$24,$B$24,$C$24) -> #VALUE! | E31: =Wedge_multiplier(A31/COS($F$24),$E$24,$A$24,$B$24,$C$24) -> #VALUE! | F31: =Wedge_wavedrageCoef(A31/COS($F$24),$E$24,$A$24,$B$24,$C$24) -> #VALUE! | H31: =Wedge_multiplier(A31,$E$24,$A$24,$B$24,$C$24) -> #VALUE! | I31: =Wedge_wavedrageCoef(A31,$E$24,$A$24,$B$24,$C$24) -> #VALUE! | K31: 1.4 | L31: =K31/COS($F$24) -> #VALUE! | M31: 1.3181458 | O31: =A31*COS($Q$24) -> #VALUE! | P31: =Wedge_multiplier(A31,$E$24,$N$24,$O$24,$P$24) -> #VALUE! | Q31: =Wedge_wavedrageCoef(A31,$E$24,$N$24,$O$24,$P$24) -> #VALUE! | S31: =A31*COS($V$24) -> #VALUE! | T31: =Wedge_multiplier(A31,$E$24,$S$24,$T$24,$U$24) -> #VALUE! | U31: =Wedge_wavedrageCoef(A31,$E$24,$S$24,$T$24,$U$24) -> #VALUE! | Y31: 4 | Z31: 3 | AA31: 1.5 | AB31: =LEsweepangle(Y31,Z31,AA31) -> #VALUE! | AD31: =SQRT(1+Z31/(2*AA31)) -> 1.4142136 | AE31: =SQRT(1+1/((1/TAN(AB31))^2)) -> #VALUE! | AF31: =SQRT((Y31/Z31)^2+1) -> 1.6666667
A32: 1.3 | B32: =A32*COS($F$24) -> #VALUE! | C32: =Wedge_HalfAngle(A32,$A$24,$B$24,$C$24) -> #VALUE! | E32: =Wedge_multiplier(A32/COS($F$24),$E$24,$A$24,$B$24,$C$24) -> #VALUE! | F32: =Wedge_wavedrageCoef(A32/COS($F$24),$E$24,$A$24,$B$24,$C$24) -> #VALUE! | H32: =Wedge_multiplier(A32,$E$24,$A$24,$B$24,$C$24) -> #VALUE! | I32: =Wedge_wavedrageCoef(A32,$E$24,$A$24,$B$24,$C$24) -> #VALUE! | K32: 1.5 | L32: =K32/COS($F$24) -> #VALUE! | M32: 1.2657804 | O32: =A32*COS($Q$24) -> #VALUE! | P32: =Wedge_multiplier(A32,$E$24,$N$24,$O$24,$P$24) -> #VALUE! | Q32: =Wedge_wavedrageCoef(A32,$E$24,$N$24,$O$24,$P$24) -> #VALUE! | S32: =A32*COS($V$24) -> #VALUE! | T32: =Wedge_multiplier(A32,$E$24,$S$24,$T$24,$U$24) -> #VALUE! | U32: =Wedge_wavedrageCoef(A32,$E$24,$S$24,$T$24,$U$24) -> #VALUE!
